<sdf version='1.6'>
  <world name='default'>
    <light name='sun' type='directional'>
      <cast_shadows>1</cast_shadows>
      <pose frame=''>0 0 10 0 -0 0</pose>
      <diffuse>0.8 0.8 0.8 1</diffuse>
      <specular>0.2 0.2 0.2 1</specular>
      <attenuation>
        <range>1000</range>
        <constant>0.9</constant>
        <linear>0.01</linear>
        <quadratic>0.001</quadratic>
      </attenuation>
      <direction>-0.5 0.1 -0.9</direction>
    </light>
    <model name='ground_plane'>
      <static>1</static>
      <link name='link'>
        <collision name='collision'>
          <geometry>
            <plane>
              <normal>0 0 1</normal>
              <size>100 100</size>
            </plane>
          </geometry>
          <surface>
            <contact>
              <collide_bitmask>65535</collide_bitmask>
              <ode/>
            </contact>
            <friction>
              <ode>
                <mu>100</mu>
                <mu2>50</mu2>
              </ode>
              <torsional>
                <ode/>
              </torsional>
            </friction>
            <bounce/>
          </surface>
          <max_contacts>10</max_contacts>
        </collision>
        <visual name='visual'>
          <cast_shadows>0</cast_shadows>
          <geometry>
            <plane>
              <normal>0 0 1</normal>
              <size>100 100</size>
            </plane>
          </geometry>
          <material>
            <script>
              <uri>file://media/materials/scripts/gazebo.material</uri>
              <name>Gazebo/Grey</name>
            </script>
          </material>
        </visual>
        <self_collide>0</self_collide>
        <enable_wind>0</enable_wind>
        <kinematic>0</kinematic>
      </link>
    </model>
    <gravity>0 0 -9.8</gravity>
    <magnetic_field>6e-06 2.3e-05 -4.2e-05</magnetic_field>
    <atmosphere type='adiabatic'/>
    <physics name='default_physics' default='0' type='ode'>
      <max_step_size>0.001</max_step_size>
      <real_time_factor>1</real_time_factor>
      <real_time_update_rate>1000</real_time_update_rate>
    </physics>
    <scene>
      <ambient>0.4 0.4 0.4 1</ambient>
      <background>0.7 0.7 0.7 1</background>
      <shadows>1</shadows>
    </scene>
    <audio>
      <device>default</device>
    </audio>
    <wind/>
    <spherical_coordinates>
      <surface_model>EARTH_WGS84</surface_model>
      <latitude_deg>0</latitude_deg>
      <longitude_deg>0</longitude_deg>
      <elevation>0</elevation>
      <heading_deg>0</heading_deg>
    </spherical_coordinates>
    <model name='environment'>
      <static>1</static>
      <link name='base'>
        <pose frame=''>0 0 0 0 -0 0</pose>
        <visual name='visual'>
          <geometry>
            <mesh>
              <uri>model://environment/meshes/environment.stl</uri>
              <scale>0.7 0.7 0.7</scale>
            </mesh>
          </geometry>
        </visual>
        <collision name='environment_collision'>
          <geometry>
            <mesh>
              <uri>model://environment/meshes/environment.stl</uri>
              <scale>0.7 0.7 0.7</scale>
            </mesh>
          </geometry>
          <surface>
            <friction>
              <ode>
                <mu>1</mu>
                <mu2>1</mu2>
              </ode>
              <torsional>
                <ode/>
              </torsional>
            </friction>
            <contact>
              <ode/>
            </contact>
            <bounce/>
          </surface>
          <max_contacts>10</max_contacts>
        </collision>
        <self_collide>0</self_collide>
        <enable_wind>0</enable_wind>
        <kinematic>0</kinematic>
      </link>
      <pose frame=''>-6.08425 -1.50036 0 0 -0 0</pose>
    </model>
    <state world_name='default'>
      <sim_time>2244 881000000</sim_time>
      <real_time>295 381132532</real_time>
      <wall_time>1623189807 58435792</wall_time>
      <iterations>255602</iterations>
      <model name='RegionEventBox'>
        <pose frame=''>1.43786 1.94267 0 0 -0 0</pose>
        <scale>1 1 1</scale>
        <link name='link'>
          <pose frame=''>1.43786 1.94267 0 0 -0 0</pose>
          <velocity>0 0 0 0 -0 0</velocity>
          <acceleration>0 0 0 0 -0 0</acceleration>
          <wrench>0 0 0 0 -0 0</wrench>
        </link>
      </model>
      <model name='environment'>
        <pose frame=''>-4.65918 1.68243 -1.05 1.57 -0 0</pose>
        <scale>1 1 1</scale>
        <link name='base'>
          <pose frame=''>-4.65918 1.68243 -1.05 1.57 -0 0</pose>
          <velocity>0 0 0 0 -0 0</velocity>
          <acceleration>0 0 0 0 -0 0</acceleration>
          <wrench>0 0 0 0 -0 0</wrench>
        </link>
      </model>
      <model name='grey_wall'>
        <pose frame=''>-3.41093 -3.39324 0 0 -0 0</pose>
        <scale>1 1 1</scale>
        <link name='link'>
          <pose frame=''>-3.41093 -3.39324 1.4 0 -0 0</pose>
          <velocity>0 0 0 0 -0 0</velocity>
          <acceleration>0 0 0 0 -0 0</acceleration>
          <wrench>0 0 0 0 -0 0</wrench>
        </link>
      </model>
      <model name='grey_wall_clone'>
        <pose frame=''>0.493325 -3.39484 0 0 -0 0</pose>
        <scale>1 1 1</scale>
        <link name='link'>
          <pose frame=''>0.493325 -3.39484 1.4 0 -0 0</pose>
          <velocity>0 0 0 0 -0 0</velocity>
          <acceleration>0 0 0 0 -0 0</acceleration>
          <wrench>0 0 0 0 -0 0</wrench>
        </link>
      </model>
      <model name='grey_wall_clone_0'>
        <pose frame=''>-3.24054 3.85909 0 0 -0 0</pose>
        <scale>1 1 1</scale>
        <link name='link'>
          <pose frame=''>-3.24054 3.85909 1.4 0 -0 0</pose>
          <velocity>0 0 0 0 -0 0</velocity>
          <acceleration>0 0 0 0 -0 0</acceleration>
          <wrench>0 0 0 0 -0 0</wrench>
        </link>
      </model>
      <model name='grey_wall_clone_1'>
        <pose frame=''>0.505871 3.84952 0 0 -0 0</pose>
        <scale>1 1 1</scale>
        <link name='link'>
          <pose frame=''>0.505871 3.84952 1.4 0 -0 0</pose>
          <velocity>0 0 0 0 -0 0</velocity>
          <acceleration>0 0 0 0 -0 0</acceleration>
          <wrench>0 0 0 0 -0 0</wrench>
        </link>
      </model>
      <model name='grey_wall_clone_2'>
        <pose frame=''>4.12308 0.246588 0 0 -0 1.57</pose>
        <scale>1 1 1</scale>
        <link name='link'>
          <pose frame=''>4.12308 0.246588 1.4 0 -0 1.57</pose>
          <velocity>0 0 0 0 -0 0</velocity>
          <acceleration>0 0 0 0 -0 0</acceleration>
          <wrench>0 0 0 0 -0 0</wrench>
        </link>
      </model>
      <model name='grey_wall_clone_2_clone_1'>
        <pose frame=''>-7.08402 0.228334 0 0 -0 1.57</pose>
        <scale>1 1 1</scale>
        <link name='link'>
          <pose frame=''>-7.08402 0.228334 1.4 0 -0 1.57</pose>
          <velocity>0 0 0 0 -0 0</velocity>
          <acceleration>0 0 0 0 -0 0</acceleration>
          <wrench>0 0 0 0 -0 0</wrench>
        </link>
      </model>
      <model name='ground_plane'>
        <pose frame=''>0 0 0 0 -0 0</pose>
        <scale>1 1 1</scale>
        <link name='link'>
          <pose frame=''>0 0 0 0 -0 0</pose>
          <velocity>0 0 0 0 -0 0</velocity>
          <acceleration>0 0 0 0 -0 0</acceleration>
          <wrench>0 0 0 0 -0 0</wrench>
        </link>
      </model>
      <model name='postbox'>
        <pose frame=''>3.02376 2.74526 0 0 -0 0</pose>
        <scale>1 1 1</scale>
        <link name='link'>
          <pose frame=''>3.02376 2.74526 0 0 -0 0</pose>
          <velocity>0 0 0 0 -0 0</velocity>
          <acceleration>0 0 0 0 -0 0</acceleration>
          <wrench>0 0 0 0 -0 0</wrench>
        </link>
      </model>
      <model name='ragdoll'>
        <pose frame=''>3.65444 -1.82041 1.39953 0.000312 -0.000444 -0.058178</pose>
        <scale>1 1 1</scale>
        <link name='head'>
          <pose frame=''>3.65446 -1.82079 2.62453 0.00032 -5.2e-05 0.000163</pose>
          <velocity>3e-06 5e-05 -3.2e-05 -0.000153 -0 0</velocity>
          <acceleration>-0.00082 -0.012985 0.009179 -0.023376 -4e-06 3e-06</acceleration>
          <wrench>-0.008196 -0.129845 0.091793 0 -0 0</wrench>
        </link>
        <link name='hip'>
          <pose frame=''>3.65444 -1.82041 1.39953 0.000312 -0.000444 -0.058178</pose>
          <velocity>-4e-06 -1.2e-05 -2.9e-05 -9e-06 2.6e-05 1.6e-05</velocity>
          <acceleration>-0.001282 0.009335 0.00729 0.019315 0.009713 0.000569</acceleration>
          <wrench>-0.012822 0.093355 0.072903 0 -0 0</wrench>
        </link>
        <link name='l_ankle'>
          <pose frame=''>3.65416 -1.60043 0.075 0.000285 5e-06 0.00188</pose>
          <velocity>-9e-06 5.1e-05 -6e-06 4.7e-05 -0.000225 1e-05</velocity>
          <acceleration>0.001036 0.110733 0.00351 0.059568 0.043846 -0.021764</acceleration>
          <wrench>0.001036 0.110733 0.00351 0 -0 0</wrench>
        </link>
        <link name='l_calf'>
          <pose frame=''>3.67529 -1.60057 0.699642 0.000285 0.033818 0.001889</pose>
          <velocity>2.3e-05 2.1e-05 -1.8e-05 4.8e-05 6.6e-05 2e-05</velocity>
          <acceleration>0.01083 0.068276 0.005972 0.063576 0.012086 -0.011864</acceleration>
          <wrench>0.02166 0.136552 0.011945 0 -0 0</wrench>
        </link>
        <link name='l_foot'>
          <pose frame=''>3.65416 -1.60042 0.05 0 7e-06 0.00188</pose>
          <velocity>-3e-06 5e-05 1.6e-05 -0.001 -6.2e-05 0</velocity>
          <acceleration>-0.000141 0.104142 -0.001966 -2.08283 -0.002823 1.4e-05</acceleration>
          <wrench>-0.000141 0.104142 -0.001966 0 -0 0</wrench>
        </link>
        <link name='l_forearm'>
          <pose frame=''>3.65552 -1.49262 1.7224 0.000137 0.002198 -0.058178</pose>
          <velocity>-3e-06 9e-06 -4.9e-05 -2.3e-05 -6e-06 1.5e-05</velocity>
          <acceleration>0.001036 -0.003997 0.016136 0.01062 0.002 0.000362</acceleration>
          <wrench>0.001036 -0.003997 0.016136 0 -0 0</wrench>
        </link>
        <link name='l_hand'>
          <pose frame=''>3.65451 -1.4925 1.2424 0.000137 -0.000259 -0.058178</pose>
          <velocity>-0 -2e-06 -4.8e-05 -2.3e-05 1e-06 1.5e-05</velocity>
          <acceleration>0.000114 0.000882 0.016045 0.010424 -0.000607 0.000364</acceleration>
          <wrench>0.000114 0.000882 0.016045 0 -0 0</wrench>
        </link>
        <link name='l_shoulder'>
          <pose frame=''>3.67346 -1.49375 2.32213 0.000137 0.000154 -0.058178</pose>
          <velocity>-3e-06 2.3e-05 -4.8e-05 -2.3e-05 -2e-06 1.5e-05</velocity>
          <acceleration>-0.000578 -0.009641 0.015986 0.009865 -0.001904 0.000359</acceleration>
          <wrench>-0.000578 -0.009641 0.015986 0 -0 0</wrench>
        </link>
        <link name='l_thigh_lift'>
          <pose frame=''>3.66723 -1.60078 1.3996 0.000285 -0.011513 0.001877</pose>
          <velocity>-8e-06 -1.1e-05 -2.4e-05 4.9e-05 -4.6e-05 2.5e-05</velocity>
          <acceleration>-0.001306 0.010882 0.00726 0.079787 -0.016925 -0.00699</acceleration>
          <wrench>-0.006532 0.05441 0.0363 0 -0 0</wrench>
        </link>
        <link name='l_thigh_pan'>
          <pose frame=''>3.66723 -1.60078 1.3996 0.000285 -0.000462 0.00188</pose>
          <velocity>-8e-06 -1e-05 -2.3e-05 5.6e-05 2.6e-05 2.7e-05</velocity>
          <acceleration>-0.0013 0.01121 0.007114 0.088198 0.009839 -0.005537</acceleration>
          <wrench>-0.0013 0.01121 0.007114 0 -0 0</wrench>
        </link>
        <link name='l_upper_arm'>
          <pose frame=''>3.67346 -1.49375 2.32213 0.000137 0.029958 -0.058174</pose>
          <velocity>-3e-06 2.3e-05 -4.8e-05 -2.3e-05 -1e-06 1.5e-05</velocity>
          <acceleration>-0.000571 -0.009585 0.015936 0.009735 -0.002209 0.000367</acceleration>
          <wrench>-0.001142 -0.01917 0.031872 0 -0 0</wrench>
        </link>
        <link name='l_wrist'>
          <pose frame=''>3.65451 -1.4925 1.2574 0.000137 -0.000267 -0.058178</pose>
          <velocity>-0 -1e-06 -4.9e-05 -2.3e-05 -0 1.5e-05</velocity>
          <acceleration>0.000107 0.00073 0.016155 0.010489 -0.000511 0.000361</acceleration>
          <wrench>0.000107 0.00073 0.016155 0 -0 0</wrench>
        </link>
        <link name='neck'>
          <pose frame=''>3.65442 -1.8207 2.34953 0.00032 0.000136 0.000164</pose>
          <velocity>2e-06 2.2e-05 -3.2e-05 -0.00016 6e-06 -0</velocity>
          <acceleration>-0.000562 -0.010723 0.009684 -0.030768 -0.000112 4e-06</acceleration>
          <wrench>-0.000562 -0.010723 0.009684 0 -0 0</wrench>
        </link>
        <link name='r_ankle'>
          <pose frame=''>3.65422 -2.03968 0.075 0.000286 7e-06 -0.001797</pose>
          <velocity>-1.4e-05 -8e-05 -4e-06 -3.4e-05 -0.000219 3.1e-05</velocity>
          <acceleration>-0.009399 -0.123539 -0.008579 -0.104885 -0.089336 0.007513</acceleration>
          <wrench>-0.009399 -0.123539 -0.008579 0 -0 0</wrench>
        </link>
        <link name='r_calf'>
          <pose frame=''>3.63047 -2.03982 0.699548 0.000287 -0.038018 -0.001808</pose>
          <velocity>-0.000154 -5.4e-05 -1.3e-05 -3.7e-05 -0.000229 1.6e-05</velocity>
          <acceleration>-0.000933 -0.057378 -0.005075 -0.107957 0.018787 -0.014851</acceleration>
          <wrench>-0.001866 -0.114756 -0.01015 0 -0 0</wrench>
        </link>
        <link name='r_foot'>
          <pose frame=''>3.65422 -2.03967 0.05 1e-06 9e-06 -0.001797</pose>
          <velocity>-8e-06 -7e-05 3e-06 0.001397 -0.000167 1e-06</velocity>
          <acceleration>-0.006816 -0.116321 -0.001181 2.3249 -0.136432 0.0008</acceleration>
          <wrench>-0.006816 -0.116321 -0.001181 0 -0 0</wrench>
        </link>
        <link name='r_forearm'>
          <pose frame=''>3.65343 -2.14809 1.7222 0.001 -0.002463 -0.058181</pose>
          <velocity>2e-06 4e-06 -2.1e-05 -1.5e-05 3e-06 1.5e-05</velocity>
          <acceleration>-0.000362 -0.005886 0.000268 0.01241 -0.000767 0.000142</acceleration>
          <wrench>-0.000362 -0.005886 0.000268 0 -0 0</wrench>
        </link>
        <link name='r_hand'>
          <pose frame=''>3.6546 -2.14768 1.2422 0.001 -0.000122 -0.058178</pose>
          <velocity>0 -2e-06 -2.2e-05 -1.2e-05 0 1.5e-05</velocity>
          <acceleration>7.9e-05 0.001384 0.000342 0.017508 -0.00102 8.3e-05</acceleration>
          <wrench>7.9e-05 0.001384 0.000342 0 -0 0</wrench>
        </link>
        <link name='r_shoulder'>
          <pose frame=''>3.63538 -2.14764 2.32192 0.001 0.000154 -0.058178</pose>
          <velocity>7e-06 1.4e-05 -1.9e-05 -1.4e-05 -2e-06 1.6e-05</velocity>
          <acceleration>-0.000552 -0.012182 0.000143 0.014031 -0.002234 0.000424</acceleration>
          <wrench>-0.000552 -0.012182 0.000143 0 -0 0</wrench>
        </link>
        <link name='r_thigh_lift'>
          <pose frame=''>3.64165 -2.04004 1.39946 0.000286 0.015976 -0.001792</pose>
          <velocity>-1e-06 -1.2e-05 -1.7e-05 -5.3e-05 0.00022 9e-06</velocity>
          <acceleration>-0.001323 0.007628 -0.003366 -0.104219 -0.001346 -0.026329</acceleration>
          <wrench>-0.006616 0.03814 -0.016832 0 -0 0</wrench>
        </link>
        <link name='r_thigh_pan'>
          <pose frame=''>3.64165 -2.04004 1.39946 0.000286 -0.000461 -0.001797</pose>
          <velocity>-1e-06 -1.2e-05 -1.7e-05 -5.4e-05 2.8e-05 6e-06</velocity>
          <acceleration>-0.001339 0.00752 -0.003973 -0.120063 0.009521 -0.030292</acceleration>
          <wrench>-0.001339 0.00752 -0.003973 0 -0 0</wrench>
        </link>
        <link name='r_upper_arm'>
          <pose frame=''>3.63538 -2.14764 2.32192 0.001001 -0.03008 -0.058208</pose>
          <velocity>7e-06 1.3e-05 -2e-05 -1.4e-05 9e-06 1.5e-05</velocity>
          <acceleration>-0.000622 -0.012968 0.000234 0.014259 -0.000631 0.000252</acceleration>
          <wrench>-0.001244 -0.025935 0.000468 0 -0 0</wrench>
        </link>
        <link name='r_wrist'>
          <pose frame=''>3.6546 -2.14769 1.2572 0.001 -9.6e-05 -0.058178</pose>
          <velocity>0 -2e-06 -2.1e-05 -1.2e-05 1e-06 1.5e-05</velocity>
          <acceleration>6.1e-05 0.001074 0.000315 0.01663 -0.000971 0.000112</acceleration>
          <wrench>6.1e-05 0.001074 0.000315 0 -0 0</wrench>
        </link>
        <link name='torso'>
          <pose frame=''>3.65433 -1.82048 1.64953 0.000312 0.000154 -0.058178</pose>
          <velocity>2e-06 -1e-05 -3e-05 -3.7e-05 -1e-06 1.6e-05</velocity>
          <acceleration>0.001195 0.003655 0.007996 0.02172 -0.002598 0.000413</acceleration>
          <wrench>0.035862 0.109653 0.239889 0 -0 0</wrench>
        </link>
      </model>
      <model name='shelf2'>
        <pose frame=''>-6.54608 -2.81903 0 0 -0 0</pose>
        <scale>1 1 1</scale>
        <link name='shelving_brackets1'>
          <pose frame=''>-6.54608 -2.81903 0.48 0 -0 0</pose>
          <velocity>0 0 0 0 -0 0</velocity>
          <acceleration>0 0 0 0 -0 0</acceleration>
          <wrench>0 0 0 0 -0 0</wrench>
        </link>
        <link name='shelving_brackets2'>
          <pose frame=''>-6.54608 -2.81903 0.95 0 -0 0</pose>
          <velocity>0 0 0 0 -0 0</velocity>
          <acceleration>0 0 0 0 -0 0</acceleration>
          <wrench>0 0 0 0 -0 0</wrench>
        </link>
        <link name='shelving_uprights'>
          <pose frame=''>-6.54608 -2.81903 0 0 -0 0</pose>
          <velocity>0 0 0 0 -0 0</velocity>
          <acceleration>0 0 0 0 -0 0</acceleration>
          <wrench>0 0 0 0 -0 0</wrench>
        </link>
      </model>
      <model name='shelf2_0'>
        <pose frame=''>-6.69653 3.22734 0 0 -0 0</pose>
        <scale>1 1 1</scale>
        <link name='shelving_brackets1'>
          <pose frame=''>-6.69653 3.22734 0.48 0 -0 0</pose>
          <velocity>0 0 0 0 -0 0</velocity>
          <acceleration>0 0 0 0 -0 0</acceleration>
          <wrench>0 0 0 0 -0 0</wrench>
        </link>
        <link name='shelving_brackets2'>
          <pose frame=''>-6.69653 3.22734 0.95 0 -0 0</pose>
          <velocity>0 0 0 0 -0 0</velocity>
          <acceleration>0 0 0 0 -0 0</acceleration>
          <wrench>0 0 0 0 -0 0</wrench>
        </link>
        <link name='shelving_uprights'>
          <pose frame=''>-6.69653 3.22734 0 0 -0 0</pose>
          <velocity>0 0 0 0 -0 0</velocity>
          <acceleration>0 0 0 0 -0 0</acceleration>
          <wrench>0 0 0 0 -0 0</wrench>
        </link>
      </model>
      <model name='unit_box'>
        <pose frame=''>1.0812 -1.77209 0.499995 -1e-05 0 0</pose>
        <scale>1 1 1</scale>
        <link name='link'>
          <pose frame=''>1.0812 -1.77209 0.499995 -1e-05 0 0</pose>
          <velocity>0 0 0 0 -0 0</velocity>
          <acceleration>-0.004709 0.011055 -9.78158 -0.022108 -0.009414 -1e-06</acceleration>
          <wrench>-0.004709 0.011055 -9.78158 0 -0 0</wrench>
        </link>
      </model>
      <model name='unit_box_0'>
        <pose frame=''>-3.45411 2.02562 0.4 0 -0 5e-06</pose>
        <scale>0.8 0.8 0.8</scale>
        <link name='link'>
          <pose frame=''>-3.45411 2.02562 0.4 0 -0 5e-06</pose>
          <velocity>0 0 0 0 -0 0</velocity>
          <acceleration>0 0 -0 0 -0 0</acceleration>
          <wrench>0 0 -0 0 -0 0</wrench>
        </link>
      </model>
      <model name='unit_cylinder'>
        <pose frame=''>-4.15386 -1.74666 0.2 0 0 -1.1e-05</pose>
        <scale>0.4 0.4 0.4</scale>
        <link name='link'>
          <pose frame=''>-4.15386 -1.74666 0.2 0 0 -1.1e-05</pose>
          <velocity>0 0 0 0 -0 0</velocity>
          <acceleration>0 -4.9e-05 -0 0.000237 -0 -5.2e-05</acceleration>
          <wrench>0 -4.9e-05 -0 0 -0 0</wrench>
        </link>
      </model>
      <model name='unit_cylinder_0'>
        <pose frame=''>-0.706807 1.87968 0.199992 -1e-06 -0 -0.020261</pose>
        <scale>0.4 0.4 0.4</scale>
        <link name='link'>
          <pose frame=''>-0.706807 1.87968 0.199992 -1e-06 -0 -0.020261</pose>
          <velocity>0 0 0 0 -0 0</velocity>
          <acceleration>0 0 -9.8 0 -0 0</acceleration>
          <wrench>0 0 -9.8 0 -0 0</wrench>
        </link>
      </model>
      <model name='warehouse_robot'>
        <pose frame=''>-1.68814 -1.84723 -0 0 -0 0</pose>
        <scale>1 1 1</scale>
        <link name='link'>
          <pose frame=''>-1.68814 -1.84723 -0 0 -0 0</pose>
          <velocity>0 0 0 0 -0 0</velocity>
          <acceleration>0 0 0 0 -0 0</acceleration>
          <wrench>0 0 0 0 -0 0</wrench>
        </link>
      </model>
      <light name='sun'>
        <pose frame=''>0 0 10 0 -0 0</pose>
      </light>
    </state>
    <gui fullscreen='0'>
      <camera name='user_camera'>
        <pose frame=''>0.980377 -0.710247 19.8432 0 1.43379 -3.08883</pose>
        <view_controller>orbit</view_controller>
        <projection_type>perspective</projection_type>
      </camera>
    </gui>
    <model name='grey_wall'>
      <static>1</static>
      <link name='link'>
        <pose frame=''>0 0 1.4 0 -0 0</pose>
        <collision name='collision'>
          <geometry>
            <box>
              <size>7.5 0.2 2.8</size>
            </box>
          </geometry>
          <max_contacts>10</max_contacts>
          <surface>
            <contact>
              <ode/>
            </contact>
            <bounce/>
            <friction>
              <torsional>
                <ode/>
              </torsional>
              <ode/>
            </friction>
          </surface>
        </collision>
        <visual name='visual'>
          <cast_shadows>0</cast_shadows>
          <geometry>
            <box>
              <size>7.5 0.2 2.8</size>
            </box>
          </geometry>
          <material>
            <script>
              <uri>model://grey_wall/materials/scripts</uri>
              <uri>model://grey_wall/materials/textures</uri>
              <name>vrc/grey_wall</name>
            </script>
          </material>
        </visual>
        <self_collide>0</self_collide>
        <enable_wind>0</enable_wind>
        <kinematic>0</kinematic>
      </link>
      <pose frame=''>-5.49021 -7.12043 0 0 -0 0</pose>
    </model>
    <model name='grey_wall_clone'>
      <static>1</static>
      <link name='link'>
        <pose frame=''>0 0 1.4 0 -0 0</pose>
        <collision name='collision'>
          <geometry>
            <box>
              <size>7.5 0.2 2.8</size>
            </box>
          </geometry>
          <max_contacts>10</max_contacts>
          <surface>
            <contact>
              <ode/>
            </contact>
            <bounce/>
            <friction>
              <torsional>
                <ode/>
              </torsional>
              <ode/>
            </friction>
          </surface>
        </collision>
        <visual name='visual'>
          <cast_shadows>0</cast_shadows>
          <geometry>
            <box>
              <size>7.5 0.2 2.8</size>
            </box>
          </geometry>
          <material>
            <script>
              <uri>model://grey_wall/materials/scripts</uri>
              <uri>model://grey_wall/materials/textures</uri>
              <name>vrc/grey_wall</name>
            </script>
          </material>
        </visual>
        <self_collide>0</self_collide>
        <enable_wind>0</enable_wind>
        <kinematic>0</kinematic>
      </link>
      <pose frame=''>1.9399 -7.10777 0 0 -0 0</pose>
    </model>
    <model name='grey_wall_clone_0'>
      <static>1</static>
      <link name='link'>
        <pose frame=''>0 0 1.4 0 -0 0</pose>
        <collision name='collision'>
          <geometry>
            <box>
              <size>7.5 0.2 2.8</size>
            </box>
          </geometry>
          <max_contacts>10</max_contacts>
          <surface>
            <contact>
              <ode/>
            </contact>
            <bounce/>
            <friction>
              <torsional>
                <ode/>
              </torsional>
              <ode/>
            </friction>
          </surface>
        </collision>
        <visual name='visual'>
          <cast_shadows>0</cast_shadows>
          <geometry>
            <box>
              <size>7.5 0.2 2.8</size>
            </box>
          </geometry>
          <material>
            <script>
              <uri>model://grey_wall/materials/scripts</uri>
              <uri>model://grey_wall/materials/textures</uri>
              <name>vrc/grey_wall</name>
            </script>
          </material>
        </visual>
        <self_collide>0</self_collide>
        <enable_wind>0</enable_wind>
        <kinematic>0</kinematic>
      </link>
      <pose frame=''>-5.14675 4.18999 0 0 -0 0</pose>
    </model>
    <model name='grey_wall_clone_1'>
      <static>1</static>
      <link name='link'>
        <pose frame=''>0 0 1.4 0 -0 0</pose>
        <collision name='collision'>
          <geometry>
            <box>
              <size>7.5 0.2 2.8</size>
            </box>
          </geometry>
          <max_contacts>10</max_contacts>
          <surface>
            <contact>
              <ode/>
            </contact>
            <bounce/>
            <friction>
              <torsional>
                <ode/>
              </torsional>
              <ode/>
            </friction>
          </surface>
        </collision>
        <visual name='visual'>
          <cast_shadows>0</cast_shadows>
          <geometry>
            <box>
              <size>7.5 0.2 2.8</size>
            </box>
          </geometry>
          <material>
            <script>
              <uri>model://grey_wall/materials/scripts</uri>
              <uri>model://grey_wall/materials/textures</uri>
              <name>vrc/grey_wall</name>
            </script>
          </material>
        </visual>
        <self_collide>0</self_collide>
        <enable_wind>0</enable_wind>
        <kinematic>0</kinematic>
      </link>
      <pose frame=''>2.23961 4.20035 0 0 -0 0</pose>
    </model>
    <model name='grey_wall_clone_2'>
      <static>1</static>
      <link name='link'>
        <pose frame=''>0 0 1.4 0 -0 0</pose>
        <collision name='collision'>
          <geometry>
            <box>
              <size>7.5 0.2 2.8</size>
            </box>
          </geometry>
          <max_contacts>10</max_contacts>
          <surface>
            <contact>
              <ode/>
            </contact>
            <bounce/>
            <friction>
              <torsional>
                <ode/>
              </torsional>
              <ode/>
            </friction>
          </surface>
        </collision>
        <visual name='visual'>
          <cast_shadows>0</cast_shadows>
          <geometry>
            <box>
              <size>7.5 0.2 2.8</size>
            </box>
          </geometry>
          <material>
            <script>
              <uri>model://grey_wall/materials/scripts</uri>
              <uri>model://grey_wall/materials/textures</uri>
              <name>vrc/grey_wall</name>
            </script>
          </material>
        </visual>
        <self_collide>0</self_collide>
        <enable_wind>0</enable_wind>
        <kinematic>0</kinematic>
      </link>
      <pose frame=''>3.69251 -4.30679 0 0 -0 0</pose>
    </model>
    <model name='grey_wall_clone_2_clone_1'>
      <static>1</static>
      <link name='link'>
        <pose frame=''>0 0 1.4 0 -0 0</pose>
        <collision name='collision'>
          <geometry>
            <box>
              <size>7.5 0.2 2.8</size>
            </box>
          </geometry>
          <max_contacts>10</max_contacts>
          <surface>
            <contact>
              <ode/>
            </contact>
            <bounce/>
            <friction>
              <torsional>
                <ode/>
              </torsional>
              <ode/>
            </friction>
          </surface>
        </collision>
        <visual name='visual'>
          <cast_shadows>0</cast_shadows>
          <geometry>
            <box>
              <size>7.5 0.2 2.8</size>
            </box>
          </geometry>
          <material>
            <script>
              <uri>model://grey_wall/materials/scripts</uri>
              <uri>model://grey_wall/materials/textures</uri>
              <name>vrc/grey_wall</name>
            </script>
          </material>
        </visual>
        <self_collide>0</self_collide>
        <enable_wind>0</enable_wind>
        <kinematic>0</kinematic>
      </link>
      <pose frame=''>-7.00075 3.9322 0 0 -0 1.57</pose>
    </model>
    <model name='unit_box_0'>
      <pose frame=''>-3.45413 4.54361 0.5 0 -0 0</pose>
      <link name='link'>
        <inertial>
          <mass>1</mass>
          <inertia>
            <ixx>0.166667</ixx>
            <ixy>0</ixy>
            <ixz>0</ixz>
            <iyy>0.166667</iyy>
            <iyz>0</iyz>
            <izz>0.166667</izz>
          </inertia>
        </inertial>
        <collision name='collision'>
          <geometry>
            <box>
              <size>1 1 1</size>
            </box>
          </geometry>
          <max_contacts>10</max_contacts>
          <surface>
            <contact>
              <ode/>
            </contact>
            <bounce/>
            <friction>
              <torsional>
                <ode/>
              </torsional>
              <ode/>
            </friction>
          </surface>
        </collision>
        <visual name='visual'>
          <geometry>
            <box>
              <size>1 1 1</size>
            </box>
          </geometry>
          <material>
            <script>
              <name>Gazebo/Grey</name>
              <uri>file://media/materials/scripts/gazebo.material</uri>
            </script>
          </material>
        </visual>
        <self_collide>0</self_collide>
        <enable_wind>0</enable_wind>
        <kinematic>0</kinematic>
      </link>
    </model>
    <model name='shelf2'>
      <static>1</static>
      <link name='shelving_uprights'>
        <pose frame=''>0 0 0 0 -0 0</pose>
        <inertial>
          <pose frame=''>-0.156 0 0.545 0 -0 0</pose>
          <mass>12.1</mass>
          <inertia>
            <ixx>3.7396</ixx>
            <ixy>0</ixy>
            <ixz>0.3568</ixz>
            <iyy>2.9636</iyy>
            <iyz>0</iyz>
            <izz>1.3356</izz>
          </inertia>
        </inertial>
        <collision name='collision'>
          <geometry>
            <mesh>
              <uri>model://shelf/shelving_uprights.dae</uri>
            </mesh>
          </geometry>
          <max_contacts>10</max_contacts>
          <surface>
            <contact>
              <ode/>
            </contact>
            <bounce/>
            <friction>
              <torsional>
                <ode/>
              </torsional>
              <ode/>
            </friction>
          </surface>
        </collision>
        <visual name='visual'>
          <geometry>
            <mesh>
              <uri>model://shelf/shelving_uprights.dae</uri>
            </mesh>
          </geometry>
        </visual>
        <self_collide>0</self_collide>
        <enable_wind>0</enable_wind>
        <kinematic>0</kinematic>
      </link>
      <link name='shelving_brackets1'>
        <pose frame=''>0 0 0.48 0 -0 0</pose>
        <inertial>
          <pose frame=''>-0.027 0 0.015 0 -0 0</pose>
          <mass>3.2</mass>
          <inertia>
            <ixx>0.247</ixx>
            <ixy>0</ixy>
            <ixz>0.0001</ixz>
            <iyy>0.05</iyy>
            <iyz>0</iyz>
            <izz>0.2966</izz>
          </inertia>
        </inertial>
        <collision name='collision'>
          <geometry>
            <mesh>
              <uri>model://shelf/shelving_brackets.dae</uri>
            </mesh>
          </geometry>
          <max_contacts>10</max_contacts>
          <surface>
            <contact>
              <ode/>
            </contact>
            <bounce/>
            <friction>
              <torsional>
                <ode/>
              </torsional>
              <ode/>
            </friction>
          </surface>
        </collision>
        <visual name='visual'>
          <geometry>
            <mesh>
              <uri>model://shelf/shelving_brackets.dae</uri>
            </mesh>
          </geometry>
        </visual>
        <self_collide>0</self_collide>
        <enable_wind>0</enable_wind>
        <kinematic>0</kinematic>
      </link>
      <link name='shelving_brackets2'>
        <pose frame=''>0 0 0.95 0 -0 0</pose>
        <inertial>
          <pose frame=''>-0.027 0 0.015 0 -0 0</pose>
          <mass>3.2</mass>
          <inertia>
            <ixx>0.247</ixx>
            <ixy>0</ixy>
            <ixz>0.0001</ixz>
            <iyy>0.05</iyy>
            <iyz>0</iyz>
            <izz>0.2966</izz>
          </inertia>
        </inertial>
        <collision name='collision'>
          <geometry>
            <mesh>
              <uri>model://shelf/shelving_brackets.dae</uri>
            </mesh>
          </geometry>
          <max_contacts>10</max_contacts>
          <surface>
            <contact>
              <ode/>
            </contact>
            <bounce/>
            <friction>
              <torsional>
                <ode/>
              </torsional>
              <ode/>
            </friction>
          </surface>
        </collision>
        <visual name='visual'>
          <geometry>
            <mesh>
              <uri>model://shelf/shelving_brackets.dae</uri>
            </mesh>
          </geometry>
        </visual>
        <self_collide>0</self_collide>
        <enable_wind>0</enable_wind>
        <kinematic>0</kinematic>
      </link>
      <pose frame=''>-6.54608 -2.4904 0 0 -0 0</pose>
    </model>
    <model name='shelf2_0'>
      <static>1</static>
      <link name='shelving_uprights'>
        <pose frame=''>0 0 0 0 -0 0</pose>
        <inertial>
          <pose frame=''>-0.156 0 0.545 0 -0 0</pose>
          <mass>12.1</mass>
          <inertia>
            <ixx>3.7396</ixx>
            <ixy>0</ixy>
            <ixz>0.3568</ixz>
            <iyy>2.9636</iyy>
            <iyz>0</iyz>
            <izz>1.3356</izz>
          </inertia>
        </inertial>
        <collision name='collision'>
          <geometry>
            <mesh>
              <uri>model://shelf/shelving_uprights.dae</uri>
            </mesh>
          </geometry>
          <max_contacts>10</max_contacts>
          <surface>
            <contact>
              <ode/>
            </contact>
            <bounce/>
            <friction>
              <torsional>
                <ode/>
              </torsional>
              <ode/>
            </friction>
          </surface>
        </collision>
        <visual name='visual'>
          <geometry>
            <mesh>
              <uri>model://shelf/shelving_uprights.dae</uri>
            </mesh>
          </geometry>
        </visual>
        <self_collide>0</self_collide>
        <enable_wind>0</enable_wind>
        <kinematic>0</kinematic>
      </link>
      <link name='shelving_brackets1'>
        <pose frame=''>0 0 0.48 0 -0 0</pose>
        <inertial>
          <pose frame=''>-0.027 0 0.015 0 -0 0</pose>
          <mass>3.2</mass>
          <inertia>
            <ixx>0.247</ixx>
            <ixy>0</ixy>
            <ixz>0.0001</ixz>
            <iyy>0.05</iyy>
            <iyz>0</iyz>
            <izz>0.2966</izz>
          </inertia>
        </inertial>
        <collision name='collision'>
          <geometry>
            <mesh>
              <uri>model://shelf/shelving_brackets.dae</uri>
            </mesh>
          </geometry>
          <max_contacts>10</max_contacts>
          <surface>
            <contact>
              <ode/>
            </contact>
            <bounce/>
            <friction>
              <torsional>
                <ode/>
              </torsional>
              <ode/>
            </friction>
          </surface>
        </collision>
        <visual name='visual'>
          <geometry>
            <mesh>
              <uri>model://shelf/shelving_brackets.dae</uri>
            </mesh>
          </geometry>
        </visual>
        <self_collide>0</self_collide>
        <enable_wind>0</enable_wind>
        <kinematic>0</kinematic>
      </link>
      <link name='shelving_brackets2'>
        <pose frame=''>0 0 0.95 0 -0 0</pose>
        <inertial>
          <pose frame=''>-0.027 0 0.015 0 -0 0</pose>
          <mass>3.2</mass>
          <inertia>
            <ixx>0.247</ixx>
            <ixy>0</ixy>
            <ixz>0.0001</ixz>
            <iyy>0.05</iyy>
            <iyz>0</iyz>
            <izz>0.2966</izz>
          </inertia>
        </inertial>
        <collision name='collision'>
          <geometry>
            <mesh>
              <uri>model://shelf/shelving_brackets.dae</uri>
            </mesh>
          </geometry>
          <max_contacts>10</max_contacts>
          <surface>
            <contact>
              <ode/>
            </contact>
            <bounce/>
            <friction>
              <torsional>
                <ode/>
              </torsional>
              <ode/>
            </friction>
          </surface>
        </collision>
        <visual name='visual'>
          <geometry>
            <mesh>
              <uri>model://shelf/shelving_brackets.dae</uri>
            </mesh>
          </geometry>
        </visual>
        <self_collide>0</self_collide>
        <enable_wind>0</enable_wind>
        <kinematic>0</kinematic>
      </link>
      <pose frame=''>-6.56127 2.98536 0 0 -0 0</pose>
    </model>
    <model name='warehouse_robot'>
      <static>1</static>
      <link name='link'>
        <visual name='visual'>
          <geometry>
            <mesh>
              <uri>model://warehouse_robot/meshes/robot.dae</uri>
            </mesh>
          </geometry>
        </visual>
        <collision name='collision_base'>
          <pose frame=''>0 0 0.20437 0 -0 0</pose>
          <geometry>
            <box>
              <size>0.55508 1.0228 0.40874</size>
            </box>
          </geometry>
          <max_contacts>10</max_contacts>
          <surface>
            <contact>
              <ode/>
            </contact>
            <bounce/>
            <friction>
              <torsional>
                <ode/>
              </torsional>
              <ode/>
            </friction>
          </surface>
        </collision>
        <collision name='collision_bumper'>
          <pose frame=''>0 0 0.062205 0 -0 0</pose>
          <geometry>
            <box>
              <size>0.67266 1.17126 0.12441</size>
            </box>
          </geometry>
          <max_contacts>10</max_contacts>
          <surface>
            <contact>
              <ode/>
            </contact>
            <bounce/>
            <friction>
              <torsional>
                <ode/>
              </torsional>
              <ode/>
            </friction>
          </surface>
        </collision>
        <collision name='collision_column_large'>
          <pose frame=''>0 -0.27539 0.43738 0 -0 0</pose>
          <geometry>
            <cylinder>
              <radius>0.08652</radius>
              <length>0.87476</length>
            </cylinder>
          </geometry>
          <max_contacts>10</max_contacts>
          <surface>
            <contact>
              <ode/>
            </contact>
            <bounce/>
            <friction>
              <torsional>
                <ode/>
              </torsional>
              <ode/>
            </friction>
          </surface>
        </collision>
        <collision name='collision_column_small'>
          <pose frame=''>0 -0.27539 0.70424 0 -0 0</pose>
          <geometry>
            <cylinder>
              <radius>0.04261</radius>
              <length>1.40848</length>
            </cylinder>
          </geometry>
          <max_contacts>10</max_contacts>
          <surface>
            <contact>
              <ode/>
            </contact>
            <bounce/>
            <friction>
              <torsional>
                <ode/>
              </torsional>
              <ode/>
            </friction>
          </surface>
        </collision>
        <self_collide>0</self_collide>
        <enable_wind>0</enable_wind>
        <kinematic>0</kinematic>
      </link>
      <pose frame=''>0.704508 -2.84719 0 0 -0 0</pose>
    </model>
    <model name='RegionEventBox'>
      <static>1</static>
      <pose frame=''>2.68059 2.66273 0 0 -0 0</pose>
      <link name='link'>
        <visual name='visual'>
          <transparency>0.75</transparency>
          <geometry>
            <box>
              <size>1 1 1.75</size>
            </box>
          </geometry>
          <material>
            <script>
              <uri>file://media/materials/scripts/gazebo.material</uri>
              <name>Gazebo/Yellow</name>
            </script>
          </material>
        </visual>
        <self_collide>0</self_collide>
        <kinematic>0</kinematic>
        <enable_wind>0</enable_wind>
      </link>
      <plugin name='region_event_box' filename='libRegionEventBoxPlugin.so'>
        <event>
          <name>model_in_region_event_box</name>
          <type>inclusion</type>
          <active>1</active>
        </event>
      </plugin>
    </model>
    <model name='ragdoll'>
      <pose frame=''>3.56361 -3.75978 1.4 0 -0 0</pose>
      <link name='hip'>
        <inertial>
          <inertia>
            <ixx>0.1</ixx>
            <ixy>0</ixy>
            <ixz>0</ixz>
            <iyy>0.1</iyy>
            <iyz>0</iyz>
            <izz>0.1</izz>
          </inertia>
          <mass>10</mass>
        </inertial>
        <collision name='hip_geom'>
          <pose frame=''>0 0 0.125 0 -0 0</pose>
          <geometry>
            <box>
              <size>0.1 0.5 0.25</size>
            </box>
          </geometry>
          <surface>
            <friction>
              <ode>
                <mu>-1</mu>
                <mu2>-1</mu2>
                <fdir1>0 0 0</fdir1>
                <slip1>0</slip1>
                <slip2>0</slip2>
              </ode>
              <torsional>
                <ode/>
              </torsional>
            </friction>
            <bounce>
              <restitution_coefficient>0</restitution_coefficient>
              <threshold>100000</threshold>
            </bounce>
            <contact>
              <ode>
                <soft_cfm>0</soft_cfm>
                <soft_erp>0.2</soft_erp>
                <kp>1e+12</kp>
                <kd>1</kd>
                <max_vel>0</max_vel>
                <min_depth>0.001</min_depth>
              </ode>
            </contact>
          </surface>
          <laser_retro>0</laser_retro>
          <max_contacts>10</max_contacts>
        </collision>
        <visual name='hip_geom_visual'>
          <pose frame=''>0 0 0.125 0 -0 0</pose>
          <geometry>
            <box>
              <size>0.1 0.5 0.25</size>
            </box>
          </geometry>
          <cast_shadows>1</cast_shadows>
          <laser_retro>0</laser_retro>
          <transparency>0</transparency>
        </visual>
        <gravity>0</gravity>
        <self_collide>0</self_collide>
        <kinematic>0</kinematic>
        <enable_wind>0</enable_wind>
      </link>
      <link name='l_thigh_pan'>
        <pose frame=''>0 0.22 0 0 -0 0</pose>
        <inertial>
          <inertia>
            <ixx>0.01</ixx>
            <ixy>0</ixy>
            <ixz>0</ixz>
            <iyy>0.01</iyy>
            <iyz>0</iyz>
            <izz>0.01</izz>
          </inertia>
          <mass>1</mass>
        </inertial>
        <collision name='l_thigh_pan_geom'>
          <pose frame=''>0 0 -0.03 0 -0 0</pose>
          <geometry>
            <sphere>
              <radius>0.06</radius>
            </sphere>
          </geometry>
          <surface>
            <friction>
              <ode>
                <mu>-1</mu>
                <mu2>-1</mu2>
                <fdir1>0 0 0</fdir1>
                <slip1>0</slip1>
                <slip2>0</slip2>
              </ode>
              <torsional>
                <ode/>
              </torsional>
            </friction>
            <bounce>
              <restitution_coefficient>0</restitution_coefficient>
              <threshold>100000</threshold>
            </bounce>
            <contact>
              <ode>
                <soft_cfm>0</soft_cfm>
                <soft_erp>0.2</soft_erp>
                <kp>1e+12</kp>
                <kd>1</kd>
                <max_vel>0</max_vel>
                <min_depth>0.001</min_depth>
              </ode>
            </contact>
          </surface>
          <laser_retro>0</laser_retro>
          <max_contacts>10</max_contacts>
        </collision>
        <visual name='l_thigh_pan_geom_visual'>
          <pose frame=''>0 0 -0.03 0 -0 0</pose>
          <geometry>
            <sphere>
              <radius>0.06</radius>
            </sphere>
          </geometry>
          <cast_shadows>1</cast_shadows>
          <laser_retro>0</laser_retro>
          <transparency>0</transparency>
        </visual>
        <gravity>0</gravity>
        <self_collide>0</self_collide>
        <kinematic>0</kinematic>
        <enable_wind>0</enable_wind>
      </link>
      <link name='l_thigh_lift'>
        <pose frame=''>0 0.22 0 0 -0 0</pose>
        <inertial>
          <inertia>
            <ixx>0.05</ixx>
            <ixy>0</ixy>
            <ixz>0</ixz>
            <iyy>0.05</iyy>
            <iyz>0</iyz>
            <izz>0.05</izz>
          </inertia>
          <mass>5</mass>
        </inertial>
        <collision name='l_thigh_lift_geom'>
          <pose frame=''>0 0 -0.35 0 -0 0</pose>
          <geometry>
            <cylinder>
              <radius>0.06</radius>
              <length>0.7</length>
            </cylinder>
          </geometry>
          <surface>
            <friction>
              <ode>
                <mu>-1</mu>
                <mu2>-1</mu2>
                <fdir1>0 0 0</fdir1>
                <slip1>0</slip1>
                <slip2>0</slip2>
              </ode>
              <torsional>
                <ode/>
              </torsional>
            </friction>
            <bounce>
              <restitution_coefficient>0</restitution_coefficient>
              <threshold>100000</threshold>
            </bounce>
            <contact>
              <ode>
                <soft_cfm>0</soft_cfm>
                <soft_erp>0.2</soft_erp>
                <kp>1e+12</kp>
                <kd>1</kd>
                <max_vel>0</max_vel>
                <min_depth>0.001</min_depth>
              </ode>
            </contact>
          </surface>
          <laser_retro>0</laser_retro>
          <max_contacts>10</max_contacts>
        </collision>
        <visual name='l_thigh_lift_geom_visual'>
          <pose frame=''>0 0 -0.35 0 -0 0</pose>
          <geometry>
            <cylinder>
              <radius>0.06</radius>
              <length>0.7</length>
            </cylinder>
          </geometry>
          <cast_shadows>1</cast_shadows>
          <laser_retro>0</laser_retro>
          <transparency>0</transparency>
        </visual>
        <gravity>0</gravity>
        <self_collide>0</self_collide>
        <kinematic>0</kinematic>
        <enable_wind>0</enable_wind>
      </link>
      <link name='l_calf'>
        <pose frame=''>0 0.22 -0.7 0 -0 0</pose>
        <inertial>
          <inertia>
            <ixx>0.02</ixx>
            <ixy>0</ixy>
            <ixz>0</ixz>
            <iyy>0.02</iyy>
            <iyz>0</iyz>
            <izz>0.02</izz>
          </inertia>
          <mass>2</mass>
        </inertial>
        <collision name='l_calf_geom'>
          <pose frame=''>0 0 -0.3 0 -0 0</pose>
          <geometry>
            <cylinder>
              <radius>0.05</radius>
              <length>0.6</length>
            </cylinder>
          </geometry>
          <surface>
            <friction>
              <ode>
                <mu>-1</mu>
                <mu2>-1</mu2>
                <fdir1>0 0 0</fdir1>
                <slip1>0</slip1>
                <slip2>0</slip2>
              </ode>
              <torsional>
                <ode/>
              </torsional>
            </friction>
            <bounce>
              <restitution_coefficient>0</restitution_coefficient>
              <threshold>100000</threshold>
            </bounce>
            <contact>
              <ode>
                <soft_cfm>0</soft_cfm>
                <soft_erp>0.2</soft_erp>
                <kp>1e+12</kp>
                <kd>1</kd>
                <max_vel>0</max_vel>
                <min_depth>0.001</min_depth>
              </ode>
            </contact>
          </surface>
          <laser_retro>0</laser_retro>
          <max_contacts>10</max_contacts>
        </collision>
        <visual name='l_calf_geom_visual'>
          <pose frame=''>0 0 -0.3 0 -0 0</pose>
          <geometry>
            <cylinder>
              <radius>0.05</radius>
              <length>0.6</length>
            </cylinder>
          </geometry>
          <cast_shadows>1</cast_shadows>
          <laser_retro>0</laser_retro>
          <transparency>0</transparency>
        </visual>
        <gravity>0</gravity>
        <self_collide>0</self_collide>
        <kinematic>0</kinematic>
        <enable_wind>0</enable_wind>
      </link>
      <link name='l_ankle'>
        <pose frame=''>0 0.22 -1.325 0 -0 0</pose>
        <inertial>
          <inertia>
            <ixx>0.01</ixx>
            <ixy>0</ixy>
            <ixz>0</ixz>
            <iyy>0.01</iyy>
            <iyz>0</iyz>
            <izz>0.01</izz>
          </inertia>
          <mass>1</mass>
        </inertial>
        <collision name='l_ankle_geom'>
          <geometry>
            <sphere>
              <radius>0.05</radius>
            </sphere>
          </geometry>
          <surface>
            <friction>
              <ode>
                <mu>-1</mu>
                <mu2>-1</mu2>
                <fdir1>0 0 0</fdir1>
                <slip1>0</slip1>
                <slip2>0</slip2>
              </ode>
              <torsional>
                <ode/>
              </torsional>
            </friction>
            <bounce>
              <restitution_coefficient>0</restitution_coefficient>
              <threshold>100000</threshold>
            </bounce>
            <contact>
              <ode>
                <soft_cfm>0</soft_cfm>
                <soft_erp>0.2</soft_erp>
                <kp>1e+12</kp>
                <kd>1</kd>
                <max_vel>0</max_vel>
                <min_depth>0.001</min_depth>
              </ode>
            </contact>
          </surface>
          <laser_retro>0</laser_retro>
          <max_contacts>10</max_contacts>
        </collision>
        <visual name='l_ankle_geom_visual'>
          <geometry>
            <sphere>
              <radius>0.05</radius>
            </sphere>
          </geometry>
          <cast_shadows>1</cast_shadows>
          <laser_retro>0</laser_retro>
          <transparency>0</transparency>
        </visual>
        <gravity>0</gravity>
        <self_collide>0</self_collide>
        <kinematic>0</kinematic>
        <enable_wind>0</enable_wind>
      </link>
      <link name='l_foot'>
        <pose frame=''>0 0.22 -1.35 0 -0 0</pose>
        <inertial>
          <pose frame=''>0.1 0 0 0 -0 0</pose>
          <inertia>
            <ixx>0.01</ixx>
            <ixy>0</ixy>
            <ixz>0</ixz>
            <iyy>0.01</iyy>
            <iyz>0</iyz>
            <izz>0.01</izz>
          </inertia>
          <mass>1</mass>
        </inertial>
        <collision name='l_foot_geom'>
          <pose frame=''>0.1 0 -0.025 0 -0 0</pose>
          <geometry>
            <box>
              <size>0.2 0.03 0.05</size>
            </box>
          </geometry>
          <surface>
            <friction>
              <ode>
                <mu>-1</mu>
                <mu2>-1</mu2>
                <fdir1>0 0 0</fdir1>
                <slip1>0</slip1>
                <slip2>0</slip2>
              </ode>
              <torsional>
                <ode/>
              </torsional>
            </friction>
            <bounce>
              <restitution_coefficient>0</restitution_coefficient>
              <threshold>100000</threshold>
            </bounce>
            <contact>
              <ode>
                <soft_cfm>0</soft_cfm>
                <soft_erp>0.2</soft_erp>
                <kp>1e+12</kp>
                <kd>1</kd>
                <max_vel>0</max_vel>
                <min_depth>0.001</min_depth>
              </ode>
            </contact>
          </surface>
          <laser_retro>0</laser_retro>
          <max_contacts>10</max_contacts>
        </collision>
        <visual name='l_foot_geom_visual'>
          <pose frame=''>0.1 0 -0.025 0 -0 0</pose>
          <geometry>
            <box>
              <size>0.2 0.03 0.05</size>
            </box>
          </geometry>
          <cast_shadows>1</cast_shadows>
          <laser_retro>0</laser_retro>
          <transparency>0</transparency>
        </visual>
        <gravity>1</gravity>
        <self_collide>0</self_collide>
        <kinematic>0</kinematic>
        <enable_wind>0</enable_wind>
      </link>
      <link name='r_thigh_pan'>
        <pose frame=''>0 -0.22 0 0 -0 0</pose>
        <inertial>
          <inertia>
            <ixx>0.01</ixx>
            <ixy>0</ixy>
            <ixz>0</ixz>
            <iyy>0.01</iyy>
            <iyz>0</iyz>
            <izz>0.01</izz>
          </inertia>
          <mass>1</mass>
        </inertial>
        <collision name='r_thigh_pan_geom'>
          <pose frame=''>0 0 -0.03 0 -0 0</pose>
          <geometry>
            <sphere>
              <radius>0.06</radius>
            </sphere>
          </geometry>
          <surface>
            <friction>
              <ode>
                <mu>-1</mu>
                <mu2>-1</mu2>
                <fdir1>0 0 0</fdir1>
                <slip1>0</slip1>
                <slip2>0</slip2>
              </ode>
              <torsional>
                <ode/>
              </torsional>
            </friction>
            <bounce>
              <restitution_coefficient>0</restitution_coefficient>
              <threshold>100000</threshold>
            </bounce>
            <contact>
              <ode>
                <soft_cfm>0</soft_cfm>
                <soft_erp>0.2</soft_erp>
                <kp>1e+12</kp>
                <kd>1</kd>
                <max_vel>0</max_vel>
                <min_depth>0.001</min_depth>
              </ode>
            </contact>
          </surface>
          <laser_retro>0</laser_retro>
          <max_contacts>10</max_contacts>
        </collision>
        <visual name='r_thigh_pan_geom_visual'>
          <pose frame=''>0 0 -0.03 0 -0 0</pose>
          <geometry>
            <sphere>
              <radius>0.06</radius>
            </sphere>
          </geometry>
          <cast_shadows>1</cast_shadows>
          <laser_retro>0</laser_retro>
          <transparency>0</transparency>
        </visual>
        <gravity>0</gravity>
        <self_collide>0</self_collide>
        <kinematic>0</kinematic>
        <enable_wind>0</enable_wind>
      </link>
      <link name='r_thigh_lift'>
        <pose frame=''>0 -0.22 0 0 -0 0</pose>
        <inertial>
          <inertia>
            <ixx>0.05</ixx>
            <ixy>0</ixy>
            <ixz>0</ixz>
            <iyy>0.05</iyy>
            <iyz>0</iyz>
            <izz>0.05</izz>
          </inertia>
          <mass>5</mass>
        </inertial>
        <collision name='r_thigh_lift_geom'>
          <pose frame=''>0 0 -0.35 0 -0 0</pose>
          <geometry>
            <cylinder>
              <radius>0.06</radius>
              <length>0.7</length>
            </cylinder>
          </geometry>
          <surface>
            <friction>
              <ode>
                <mu>-1</mu>
                <mu2>-1</mu2>
                <fdir1>0 0 0</fdir1>
                <slip1>0</slip1>
                <slip2>0</slip2>
              </ode>
              <torsional>
                <ode/>
              </torsional>
            </friction>
            <bounce>
              <restitution_coefficient>0</restitution_coefficient>
              <threshold>100000</threshold>
            </bounce>
            <contact>
              <ode>
                <soft_cfm>0</soft_cfm>
                <soft_erp>0.2</soft_erp>
                <kp>1e+12</kp>
                <kd>1</kd>
                <max_vel>0</max_vel>
                <min_depth>0.001</min_depth>
              </ode>
            </contact>
          </surface>
          <laser_retro>0</laser_retro>
          <max_contacts>10</max_contacts>
        </collision>
        <visual name='r_thigh_lift_geom_visual'>
          <pose frame=''>0 0 -0.35 0 -0 0</pose>
          <geometry>
            <cylinder>
              <radius>0.06</radius>
              <length>0.7</length>
            </cylinder>
          </geometry>
          <cast_shadows>1</cast_shadows>
          <laser_retro>0</laser_retro>
          <transparency>0</transparency>
        </visual>
        <gravity>0</gravity>
        <self_collide>0</self_collide>
        <kinematic>0</kinematic>
        <enable_wind>0</enable_wind>
      </link>
      <link name='r_calf'>
        <pose frame=''>0 -0.22 -0.7 0 -0 0</pose>
        <inertial>
          <inertia>
            <ixx>0.02</ixx>
            <ixy>0</ixy>
            <ixz>0</ixz>
            <iyy>0.02</iyy>
            <iyz>0</iyz>
            <izz>0.02</izz>
          </inertia>
          <mass>2</mass>
        </inertial>
        <collision name='r_calf_geom'>
          <pose frame=''>0 0 -0.3 0 -0 0</pose>
          <geometry>
            <cylinder>
              <radius>0.05</radius>
              <length>0.6</length>
            </cylinder>
          </geometry>
          <surface>
            <friction>
              <ode>
                <mu>-1</mu>
                <mu2>-1</mu2>
                <fdir1>0 0 0</fdir1>
                <slip1>0</slip1>
                <slip2>0</slip2>
              </ode>
              <torsional>
                <ode/>
              </torsional>
            </friction>
            <bounce>
              <restitution_coefficient>0</restitution_coefficient>
              <threshold>100000</threshold>
            </bounce>
            <contact>
              <ode>
                <soft_cfm>0</soft_cfm>
                <soft_erp>0.2</soft_erp>
                <kp>1e+12</kp>
                <kd>1</kd>
                <max_vel>0</max_vel>
                <min_depth>0.001</min_depth>
              </ode>
            </contact>
          </surface>
          <laser_retro>0</laser_retro>
          <max_contacts>10</max_contacts>
        </collision>
        <visual name='r_calf_geom_visual'>
          <pose frame=''>0 0 -0.3 0 -0 0</pose>
          <geometry>
            <cylinder>
              <radius>0.05</radius>
              <length>0.6</length>
            </cylinder>
          </geometry>
          <cast_shadows>1</cast_shadows>
          <laser_retro>0</laser_retro>
          <transparency>0</transparency>
        </visual>
        <gravity>0</gravity>
        <self_collide>0</self_collide>
        <kinematic>0</kinematic>
        <enable_wind>0</enable_wind>
      </link>
      <link name='r_ankle'>
        <pose frame=''>0 -0.22 -1.325 0 -0 0</pose>
        <inertial>
          <inertia>
            <ixx>0.01</ixx>
            <ixy>0</ixy>
            <ixz>0</ixz>
            <iyy>0.01</iyy>
            <iyz>0</iyz>
            <izz>0.01</izz>
          </inertia>
          <mass>1</mass>
        </inertial>
        <collision name='r_ankle_geom'>
          <geometry>
            <sphere>
              <radius>0.05</radius>
            </sphere>
          </geometry>
          <surface>
            <friction>
              <ode>
                <mu>-1</mu>
                <mu2>-1</mu2>
                <fdir1>0 0 0</fdir1>
                <slip1>0</slip1>
                <slip2>0</slip2>
              </ode>
              <torsional>
                <ode/>
              </torsional>
            </friction>
            <bounce>
              <restitution_coefficient>0</restitution_coefficient>
              <threshold>100000</threshold>
            </bounce>
            <contact>
              <ode>
                <soft_cfm>0</soft_cfm>
                <soft_erp>0.2</soft_erp>
                <kp>1e+12</kp>
                <kd>1</kd>
                <max_vel>0</max_vel>
                <min_depth>0.001</min_depth>
              </ode>
            </contact>
          </surface>
          <laser_retro>0</laser_retro>
          <max_contacts>10</max_contacts>
        </collision>
        <visual name='r_ankle_geom_visual'>
          <geometry>
            <sphere>
              <radius>0.05</radius>
            </sphere>
          </geometry>
          <cast_shadows>1</cast_shadows>
          <laser_retro>0</laser_retro>
          <transparency>0</transparency>
        </visual>
        <gravity>0</gravity>
        <self_collide>0</self_collide>
        <kinematic>0</kinematic>
        <enable_wind>0</enable_wind>
      </link>
      <link name='r_foot'>
        <pose frame=''>0 -0.22 -1.35 0 -0 0</pose>
        <inertial>
          <pose frame=''>0.1 0 0 0 -0 0</pose>
          <inertia>
            <ixx>0.01</ixx>
            <ixy>0</ixy>
            <ixz>0</ixz>
            <iyy>0.01</iyy>
            <iyz>0</iyz>
            <izz>0.01</izz>
          </inertia>
          <mass>1</mass>
        </inertial>
        <collision name='r_foot_geom'>
          <pose frame=''>0.1 0 -0.025 0 -0 0</pose>
          <geometry>
            <box>
              <size>0.2 0.03 0.05</size>
            </box>
          </geometry>
          <surface>
            <friction>
              <ode>
                <mu>-1</mu>
                <mu2>-1</mu2>
                <fdir1>0 0 0</fdir1>
                <slip1>0</slip1>
                <slip2>0</slip2>
              </ode>
              <torsional>
                <ode/>
              </torsional>
            </friction>
            <bounce>
              <restitution_coefficient>0</restitution_coefficient>
              <threshold>100000</threshold>
            </bounce>
            <contact>
              <ode>
                <soft_cfm>0</soft_cfm>
                <soft_erp>0.2</soft_erp>
                <kp>1e+12</kp>
                <kd>1</kd>
                <max_vel>0</max_vel>
                <min_depth>0.001</min_depth>
              </ode>
            </contact>
          </surface>
          <laser_retro>0</laser_retro>
          <max_contacts>10</max_contacts>
        </collision>
        <visual name='r_foot_geom_visual'>
          <pose frame=''>0.1 0 -0.025 0 -0 0</pose>
          <geometry>
            <box>
              <size>0.2 0.03 0.05</size>
            </box>
          </geometry>
          <cast_shadows>1</cast_shadows>
          <laser_retro>0</laser_retro>
          <transparency>0</transparency>
        </visual>
        <gravity>1</gravity>
        <self_collide>0</self_collide>
        <kinematic>0</kinematic>
        <enable_wind>0</enable_wind>
      </link>
      <link name='torso'>
        <pose frame=''>0 0 0.25 0 -0 0</pose>
        <inertial>
          <inertia>
            <ixx>0.3</ixx>
            <ixy>0</ixy>
            <ixz>0</ixz>
            <iyy>0.3</iyy>
            <iyz>0</iyz>
            <izz>0.3</izz>
          </inertia>
          <mass>30</mass>
        </inertial>
        <collision name='torso_geom'>
          <pose frame=''>0 0 0.35 0 -0 0</pose>
          <geometry>
            <box>
              <size>0.1 0.6 0.7</size>
            </box>
          </geometry>
          <surface>
            <friction>
              <ode>
                <mu>-1</mu>
                <mu2>-1</mu2>
                <fdir1>0 0 0</fdir1>
                <slip1>0</slip1>
                <slip2>0</slip2>
              </ode>
              <torsional>
                <ode/>
              </torsional>
            </friction>
            <bounce>
              <restitution_coefficient>0</restitution_coefficient>
              <threshold>100000</threshold>
            </bounce>
            <contact>
              <ode>
                <soft_cfm>0</soft_cfm>
                <soft_erp>0.2</soft_erp>
                <kp>1e+12</kp>
                <kd>1</kd>
                <max_vel>0</max_vel>
                <min_depth>0.001</min_depth>
              </ode>
            </contact>
          </surface>
          <laser_retro>0</laser_retro>
          <max_contacts>10</max_contacts>
        </collision>
        <visual name='torso_geom_visual'>
          <pose frame=''>0 0 0.35 0 -0 0</pose>
          <geometry>
            <box>
              <size>0.1 0.6 0.7</size>
            </box>
          </geometry>
          <cast_shadows>1</cast_shadows>
          <laser_retro>0</laser_retro>
          <transparency>0</transparency>
        </visual>
        <gravity>0</gravity>
        <self_collide>0</self_collide>
        <kinematic>0</kinematic>
        <enable_wind>0</enable_wind>
      </link>
      <link name='l_shoulder'>
        <pose frame=''>0 0.3275 0.9225 0 -0 0</pose>
        <inertial>
          <inertia>
            <ixx>0.01</ixx>
            <ixy>0</ixy>
            <ixz>0</ixz>
            <iyy>0.01</iyy>
            <iyz>0</iyz>
            <izz>0.01</izz>
          </inertia>
          <mass>1</mass>
        </inertial>
        <collision name='l_shoulder_geom'>
          <geometry>
            <sphere>
              <radius>0.055</radius>
            </sphere>
          </geometry>
          <surface>
            <friction>
              <ode>
                <mu>-1</mu>
                <mu2>-1</mu2>
                <fdir1>0 0 0</fdir1>
                <slip1>0</slip1>
                <slip2>0</slip2>
              </ode>
              <torsional>
                <ode/>
              </torsional>
            </friction>
            <bounce>
              <restitution_coefficient>0</restitution_coefficient>
              <threshold>100000</threshold>
            </bounce>
            <contact>
              <ode>
                <soft_cfm>0</soft_cfm>
                <soft_erp>0.2</soft_erp>
                <kp>1e+12</kp>
                <kd>1</kd>
                <max_vel>0</max_vel>
                <min_depth>0.001</min_depth>
              </ode>
            </contact>
          </surface>
          <laser_retro>0</laser_retro>
          <max_contacts>10</max_contacts>
        </collision>
        <visual name='l_shoulder_geom_visual'>
          <geometry>
            <sphere>
              <radius>0.055</radius>
            </sphere>
          </geometry>
          <cast_shadows>1</cast_shadows>
          <laser_retro>0</laser_retro>
          <transparency>0</transparency>
        </visual>
        <gravity>0</gravity>
        <self_collide>0</self_collide>
        <kinematic>0</kinematic>
        <enable_wind>0</enable_wind>
      </link>
      <link name='l_upper_arm'>
        <pose frame=''>0 0.3275 0.9225 0 -0 0</pose>
        <inertial>
          <inertia>
            <ixx>0.02</ixx>
            <ixy>0</ixy>
            <ixz>0</ixz>
            <iyy>0.02</iyy>
            <iyz>0</iyz>
            <izz>0.02</izz>
          </inertia>
          <mass>2</mass>
        </inertial>
        <collision name='l_upper_arm_geom'>
          <pose frame=''>0 0 -0.3 0 -0 0</pose>
          <geometry>
            <cylinder>
              <radius>0.055</radius>
              <length>0.6</length>
            </cylinder>
          </geometry>
          <surface>
            <friction>
              <ode>
                <mu>-1</mu>
                <mu2>-1</mu2>
                <fdir1>0 0 0</fdir1>
                <slip1>0</slip1>
                <slip2>0</slip2>
              </ode>
              <torsional>
                <ode/>
              </torsional>
            </friction>
            <bounce>
              <restitution_coefficient>0</restitution_coefficient>
              <threshold>100000</threshold>
            </bounce>
            <contact>
              <ode>
                <soft_cfm>0</soft_cfm>
                <soft_erp>0.2</soft_erp>
                <kp>1e+12</kp>
                <kd>1</kd>
                <max_vel>0</max_vel>
                <min_depth>0.001</min_depth>
              </ode>
            </contact>
          </surface>
          <laser_retro>0</laser_retro>
          <max_contacts>10</max_contacts>
        </collision>
        <visual name='l_upper_arm_geom_visual'>
          <pose frame=''>0 0 -0.3 0 -0 0</pose>
          <geometry>
            <cylinder>
              <radius>0.055</radius>
              <length>0.6</length>
            </cylinder>
          </geometry>
          <cast_shadows>1</cast_shadows>
          <laser_retro>0</laser_retro>
          <transparency>0</transparency>
        </visual>
        <gravity>0</gravity>
        <self_collide>0</self_collide>
        <kinematic>0</kinematic>
        <enable_wind>0</enable_wind>
      </link>
      <link name='l_forearm'>
        <pose frame=''>0 0.3275 0.3225 0 -0 0</pose>
        <inertial>
          <inertia>
            <ixx>0.01</ixx>
            <ixy>0</ixy>
            <ixz>0</ixz>
            <iyy>0.01</iyy>
            <iyz>0</iyz>
            <izz>0.01</izz>
          </inertia>
          <mass>1</mass>
        </inertial>
        <collision name='l_forearm_geom'>
          <pose frame=''>0 0 -0.225 0 -0 0</pose>
          <geometry>
            <cylinder>
              <radius>0.05</radius>
              <length>0.45</length>
            </cylinder>
          </geometry>
          <surface>
            <friction>
              <ode>
                <mu>-1</mu>
                <mu2>-1</mu2>
                <fdir1>0 0 0</fdir1>
                <slip1>0</slip1>
                <slip2>0</slip2>
              </ode>
              <torsional>
                <ode/>
              </torsional>
            </friction>
            <bounce>
              <restitution_coefficient>0</restitution_coefficient>
              <threshold>100000</threshold>
            </bounce>
            <contact>
              <ode>
                <soft_cfm>0</soft_cfm>
                <soft_erp>0.2</soft_erp>
                <kp>1e+12</kp>
                <kd>1</kd>
                <max_vel>0</max_vel>
                <min_depth>0.001</min_depth>
              </ode>
            </contact>
          </surface>
          <laser_retro>0</laser_retro>
          <max_contacts>10</max_contacts>
        </collision>
        <visual name='l_forearm_geom_visual'>
          <pose frame=''>0 0 -0.225 0 -0 0</pose>
          <geometry>
            <cylinder>
              <radius>0.05</radius>
              <length>0.45</length>
            </cylinder>
          </geometry>
          <cast_shadows>1</cast_shadows>
          <laser_retro>0</laser_retro>
          <transparency>0</transparency>
        </visual>
        <gravity>0</gravity>
        <self_collide>0</self_collide>
        <kinematic>0</kinematic>
        <enable_wind>0</enable_wind>
      </link>
      <link name='l_wrist'>
        <pose frame=''>0 0.3275 -0.1425 0 -0 0</pose>
        <inertial>
          <inertia>
            <ixx>0.01</ixx>
            <ixy>0</ixy>
            <ixz>0</ixz>
            <iyy>0.01</iyy>
            <iyz>0</iyz>
            <izz>0.01</izz>
          </inertia>
          <mass>1</mass>
        </inertial>
        <collision name='l_wrist_geom'>
          <geometry>
            <sphere>
              <radius>0.03</radius>
            </sphere>
          </geometry>
          <surface>
            <friction>
              <ode>
                <mu>-1</mu>
                <mu2>-1</mu2>
                <fdir1>0 0 0</fdir1>
                <slip1>0</slip1>
                <slip2>0</slip2>
              </ode>
              <torsional>
                <ode/>
              </torsional>
            </friction>
            <bounce>
              <restitution_coefficient>0</restitution_coefficient>
              <threshold>100000</threshold>
            </bounce>
            <contact>
              <ode>
                <soft_cfm>0</soft_cfm>
                <soft_erp>0.2</soft_erp>
                <kp>1e+12</kp>
                <kd>1</kd>
                <max_vel>0</max_vel>
                <min_depth>0.001</min_depth>
              </ode>
            </contact>
          </surface>
          <laser_retro>0</laser_retro>
          <max_contacts>10</max_contacts>
        </collision>
        <visual name='l_wrist_geom_visual'>
          <geometry>
            <sphere>
              <radius>0.03</radius>
            </sphere>
          </geometry>
          <cast_shadows>1</cast_shadows>
          <laser_retro>0</laser_retro>
          <transparency>0</transparency>
        </visual>
        <gravity>0</gravity>
        <self_collide>0</self_collide>
        <kinematic>0</kinematic>
        <enable_wind>0</enable_wind>
      </link>
      <link name='l_hand'>
        <pose frame=''>0 0.3275 -0.1575 0 -0 0</pose>
        <inertial>
          <inertia>
            <ixx>0.01</ixx>
            <ixy>0</ixy>
            <ixz>0</ixz>
            <iyy>0.01</iyy>
            <iyz>0</iyz>
            <izz>0.01</izz>
          </inertia>
          <mass>1</mass>
        </inertial>
        <collision name='l_hand_geom'>
          <pose frame=''>0 0 -0.1 0 -0 0</pose>
          <geometry>
            <box>
              <size>0.03 0.1 0.2</size>
            </box>
          </geometry>
          <surface>
            <friction>
              <ode>
                <mu>-1</mu>
                <mu2>-1</mu2>
                <fdir1>0 0 0</fdir1>
                <slip1>0</slip1>
                <slip2>0</slip2>
              </ode>
              <torsional>
                <ode/>
              </torsional>
            </friction>
            <bounce>
              <restitution_coefficient>0</restitution_coefficient>
              <threshold>100000</threshold>
            </bounce>
            <contact>
              <ode>
                <soft_cfm>0</soft_cfm>
                <soft_erp>0.2</soft_erp>
                <kp>1e+12</kp>
                <kd>1</kd>
                <max_vel>0</max_vel>
                <min_depth>0.001</min_depth>
              </ode>
            </contact>
          </surface>
          <laser_retro>0</laser_retro>
          <max_contacts>10</max_contacts>
        </collision>
        <visual name='l_hand_geom_visual'>
          <pose frame=''>0 0 -0.1 0 -0 0</pose>
          <geometry>
            <box>
              <size>0.03 0.1 0.2</size>
            </box>
          </geometry>
          <cast_shadows>1</cast_shadows>
          <laser_retro>0</laser_retro>
          <transparency>0</transparency>
        </visual>
        <gravity>0</gravity>
        <self_collide>0</self_collide>
        <kinematic>0</kinematic>
        <enable_wind>0</enable_wind>
      </link>
      <link name='neck'>
        <pose frame=''>0 0 0.95 0 -0 0</pose>
        <inertial>
          <inertia>
            <ixx>0.01</ixx>
            <ixy>0</ixy>
            <ixz>0</ixz>
            <iyy>0.01</iyy>
            <iyz>0</iyz>
            <izz>0.01</izz>
          </inertia>
          <mass>1</mass>
        </inertial>
        <collision name='neck_geom'>
          <pose frame=''>0 0 0.1 0 -0 0</pose>
          <geometry>
            <cylinder>
              <radius>0.075</radius>
              <length>0.2</length>
            </cylinder>
          </geometry>
          <surface>
            <friction>
              <ode>
                <mu>-1</mu>
                <mu2>-1</mu2>
                <fdir1>0 0 0</fdir1>
                <slip1>0</slip1>
                <slip2>0</slip2>
              </ode>
              <torsional>
                <ode/>
              </torsional>
            </friction>
            <bounce>
              <restitution_coefficient>0</restitution_coefficient>
              <threshold>100000</threshold>
            </bounce>
            <contact>
              <ode>
                <soft_cfm>0</soft_cfm>
                <soft_erp>0.2</soft_erp>
                <kp>1e+12</kp>
                <kd>1</kd>
                <max_vel>0</max_vel>
                <min_depth>0.001</min_depth>
              </ode>
            </contact>
          </surface>
          <laser_retro>0</laser_retro>
          <max_contacts>10</max_contacts>
        </collision>
        <visual name='neck_geom_visual'>
          <pose frame=''>0 0 0.1 0 -0 0</pose>
          <geometry>
            <cylinder>
              <radius>0.075</radius>
              <length>0.2</length>
            </cylinder>
          </geometry>
          <cast_shadows>1</cast_shadows>
          <laser_retro>0</laser_retro>
          <transparency>0</transparency>
        </visual>
        <gravity>0</gravity>
        <self_collide>0</self_collide>
        <kinematic>0</kinematic>
        <enable_wind>0</enable_wind>
      </link>
      <link name='head'>
        <pose frame=''>0 0 1.225 0 -0 0</pose>
        <inertial>
          <inertia>
            <ixx>0.1</ixx>
            <ixy>0</ixy>
            <ixz>0</ixz>
            <iyy>0.1</iyy>
            <iyz>0</iyz>
            <izz>0.1</izz>
          </inertia>
          <mass>10</mass>
        </inertial>
        <collision name='head_geom'>
          <geometry>
            <sphere>
              <radius>0.15</radius>
            </sphere>
          </geometry>
          <surface>
            <friction>
              <ode>
                <mu>-1</mu>
                <mu2>-1</mu2>
                <fdir1>0 0 0</fdir1>
                <slip1>0</slip1>
                <slip2>0</slip2>
              </ode>
              <torsional>
                <ode/>
              </torsional>
            </friction>
            <bounce>
              <restitution_coefficient>0</restitution_coefficient>
              <threshold>100000</threshold>
            </bounce>
            <contact>
              <ode>
                <soft_cfm>0</soft_cfm>
                <soft_erp>0.2</soft_erp>
                <kp>1e+12</kp>
                <kd>1</kd>
                <max_vel>0</max_vel>
                <min_depth>0.001</min_depth>
              </ode>
            </contact>
          </surface>
          <laser_retro>0</laser_retro>
          <max_contacts>10</max_contacts>
        </collision>
        <visual name='head_geom_visual'>
          <geometry>
            <sphere>
              <radius>0.15</radius>
            </sphere>
          </geometry>
          <cast_shadows>1</cast_shadows>
          <laser_retro>0</laser_retro>
          <transparency>0</transparency>
        </visual>
        <gravity>0</gravity>
        <self_collide>0</self_collide>
        <kinematic>0</kinematic>
        <enable_wind>0</enable_wind>
      </link>
      <link name='r_shoulder'>
        <pose frame=''>0 -0.3275 0.9225 0 -0 0</pose>
        <inertial>
          <inertia>
            <ixx>0.01</ixx>
            <ixy>0</ixy>
            <ixz>0</ixz>
            <iyy>0.01</iyy>
            <iyz>0</iyz>
            <izz>0.01</izz>
          </inertia>
          <mass>1</mass>
        </inertial>
        <collision name='r_shoulder_geom'>
          <geometry>
            <sphere>
              <radius>0.055</radius>
            </sphere>
          </geometry>
          <surface>
            <friction>
              <ode>
                <mu>-1</mu>
                <mu2>-1</mu2>
                <fdir1>0 0 0</fdir1>
                <slip1>0</slip1>
                <slip2>0</slip2>
              </ode>
              <torsional>
                <ode/>
              </torsional>
            </friction>
            <bounce>
              <restitution_coefficient>0</restitution_coefficient>
              <threshold>100000</threshold>
            </bounce>
            <contact>
              <ode>
                <soft_cfm>0</soft_cfm>
                <soft_erp>0.2</soft_erp>
                <kp>1e+12</kp>
                <kd>1</kd>
                <max_vel>0</max_vel>
                <min_depth>0.001</min_depth>
              </ode>
            </contact>
          </surface>
          <laser_retro>0</laser_retro>
          <max_contacts>10</max_contacts>
        </collision>
        <visual name='r_shoulder_geom_visual'>
          <geometry>
            <sphere>
              <radius>0.055</radius>
            </sphere>
          </geometry>
          <cast_shadows>1</cast_shadows>
          <laser_retro>0</laser_retro>
          <transparency>0</transparency>
        </visual>
        <gravity>0</gravity>
        <self_collide>0</self_collide>
        <kinematic>0</kinematic>
        <enable_wind>0</enable_wind>
      </link>
      <link name='r_upper_arm'>
        <pose frame=''>0 -0.3275 0.9225 0 -0 0</pose>
        <inertial>
          <inertia>
            <ixx>0.02</ixx>
            <ixy>0</ixy>
            <ixz>0</ixz>
            <iyy>0.02</iyy>
            <iyz>0</iyz>
            <izz>0.02</izz>
          </inertia>
          <mass>2</mass>
        </inertial>
        <collision name='r_upper_arm_geom'>
          <pose frame=''>0 0 -0.3 0 -0 0</pose>
          <geometry>
            <cylinder>
              <radius>0.055</radius>
              <length>0.6</length>
            </cylinder>
          </geometry>
          <surface>
            <friction>
              <ode>
                <mu>-1</mu>
                <mu2>-1</mu2>
                <fdir1>0 0 0</fdir1>
                <slip1>0</slip1>
                <slip2>0</slip2>
              </ode>
              <torsional>
                <ode/>
              </torsional>
            </friction>
            <bounce>
              <restitution_coefficient>0</restitution_coefficient>
              <threshold>100000</threshold>
            </bounce>
            <contact>
              <ode>
                <soft_cfm>0</soft_cfm>
                <soft_erp>0.2</soft_erp>
                <kp>1e+12</kp>
                <kd>1</kd>
                <max_vel>0</max_vel>
                <min_depth>0.001</min_depth>
              </ode>
            </contact>
          </surface>
          <laser_retro>0</laser_retro>
          <max_contacts>10</max_contacts>
        </collision>
        <visual name='r_upper_arm_geom_visual'>
          <pose frame=''>0 0 -0.3 0 -0 0</pose>
          <geometry>
            <cylinder>
              <radius>0.055</radius>
              <length>0.6</length>
            </cylinder>
          </geometry>
          <cast_shadows>1</cast_shadows>
          <laser_retro>0</laser_retro>
          <transparency>0</transparency>
        </visual>
        <gravity>0</gravity>
        <self_collide>0</self_collide>
        <kinematic>0</kinematic>
        <enable_wind>0</enable_wind>
      </link>
      <link name='r_forearm'>
        <pose frame=''>0 -0.3275 0.3225 0 -0 0</pose>
        <inertial>
          <inertia>
            <ixx>0.01</ixx>
            <ixy>0</ixy>
            <ixz>0</ixz>
            <iyy>0.01</iyy>
            <iyz>0</iyz>
            <izz>0.01</izz>
          </inertia>
          <mass>1</mass>
        </inertial>
        <collision name='r_forearm_geom'>
          <pose frame=''>0 0 -0.225 0 -0 0</pose>
          <geometry>
            <cylinder>
              <radius>0.05</radius>
              <length>0.45</length>
            </cylinder>
          </geometry>
          <surface>
            <friction>
              <ode>
                <mu>-1</mu>
                <mu2>-1</mu2>
                <fdir1>0 0 0</fdir1>
                <slip1>0</slip1>
                <slip2>0</slip2>
              </ode>
              <torsional>
                <ode/>
              </torsional>
            </friction>
            <bounce>
              <restitution_coefficient>0</restitution_coefficient>
              <threshold>100000</threshold>
            </bounce>
            <contact>
              <ode>
                <soft_cfm>0</soft_cfm>
                <soft_erp>0.2</soft_erp>
                <kp>1e+12</kp>
                <kd>1</kd>
                <max_vel>0</max_vel>
                <min_depth>0.001</min_depth>
              </ode>
            </contact>
          </surface>
          <laser_retro>0</laser_retro>
          <max_contacts>10</max_contacts>
        </collision>
        <visual name='r_forearm_geom_visual'>
          <pose frame=''>0 0 -0.225 0 -0 0</pose>
          <geometry>
            <cylinder>
              <radius>0.05</radius>
              <length>0.45</length>
            </cylinder>
          </geometry>
          <cast_shadows>1</cast_shadows>
          <laser_retro>0</laser_retro>
          <transparency>0</transparency>
        </visual>
        <gravity>0</gravity>
        <self_collide>0</self_collide>
        <kinematic>0</kinematic>
        <enable_wind>0</enable_wind>
      </link>
      <link name='r_wrist'>
        <pose frame=''>0 -0.3275 -0.1425 0 -0 0</pose>
        <inertial>
          <inertia>
            <ixx>0.01</ixx>
            <ixy>0</ixy>
            <ixz>0</ixz>
            <iyy>0.01</iyy>
            <iyz>0</iyz>
            <izz>0.01</izz>
          </inertia>
          <mass>1</mass>
        </inertial>
        <collision name='r_wrist_geom'>
          <geometry>
            <sphere>
              <radius>0.03</radius>
            </sphere>
          </geometry>
          <surface>
            <friction>
              <ode>
                <mu>-1</mu>
                <mu2>-1</mu2>
                <fdir1>0 0 0</fdir1>
                <slip1>0</slip1>
                <slip2>0</slip2>
              </ode>
              <torsional>
                <ode/>
              </torsional>
            </friction>
            <bounce>
              <restitution_coefficient>0</restitution_coefficient>
              <threshold>100000</threshold>
            </bounce>
            <contact>
              <ode>
                <soft_cfm>0</soft_cfm>
                <soft_erp>0.2</soft_erp>
                <kp>1e+12</kp>
                <kd>1</kd>
                <max_vel>0</max_vel>
                <min_depth>0.001</min_depth>
              </ode>
            </contact>
          </surface>
          <laser_retro>0</laser_retro>
          <max_contacts>10</max_contacts>
        </collision>
        <visual name='r_wrist_geom_visual'>
          <geometry>
            <sphere>
              <radius>0.03</radius>
            </sphere>
          </geometry>
          <cast_shadows>1</cast_shadows>
          <laser_retro>0</laser_retro>
          <transparency>0</transparency>
        </visual>
        <gravity>0</gravity>
        <self_collide>0</self_collide>
        <kinematic>0</kinematic>
        <enable_wind>0</enable_wind>
      </link>
      <link name='r_hand'>
        <pose frame=''>0 -0.3275 -0.1575 0 -0 0</pose>
        <inertial>
          <inertia>
            <ixx>0.01</ixx>
            <ixy>0</ixy>
            <ixz>0</ixz>
            <iyy>0.01</iyy>
            <iyz>0</iyz>
            <izz>0.01</izz>
          </inertia>
          <mass>1</mass>
        </inertial>
        <collision name='r_hand_geom'>
          <pose frame=''>0 0 -0.1 0 -0 0</pose>
          <geometry>
            <box>
              <size>0.03 0.1 0.2</size>
            </box>
          </geometry>
          <surface>
            <friction>
              <ode>
                <mu>-1</mu>
                <mu2>-1</mu2>
                <fdir1>0 0 0</fdir1>
                <slip1>0</slip1>
                <slip2>0</slip2>
              </ode>
              <torsional>
                <ode/>
              </torsional>
            </friction>
            <bounce>
              <restitution_coefficient>0</restitution_coefficient>
              <threshold>100000</threshold>
            </bounce>
            <contact>
              <ode>
                <soft_cfm>0</soft_cfm>
                <soft_erp>0.2</soft_erp>
                <kp>1e+12</kp>
                <kd>1</kd>
                <max_vel>0</max_vel>
                <min_depth>0.001</min_depth>
              </ode>
            </contact>
          </surface>
          <laser_retro>0</laser_retro>
          <max_contacts>10</max_contacts>
        </collision>
        <visual name='r_hand_geom_visual'>
          <pose frame=''>0 0 -0.1 0 -0 0</pose>
          <geometry>
            <box>
              <size>0.03 0.1 0.2</size>
            </box>
          </geometry>
          <cast_shadows>1</cast_shadows>
          <laser_retro>0</laser_retro>
          <transparency>0</transparency>
        </visual>
        <gravity>0</gravity>
        <self_collide>0</self_collide>
        <kinematic>0</kinematic>
        <enable_wind>0</enable_wind>
      </link>
      <joint name='l_thigh_pan_joint' type='revolute'>
        <parent>hip</parent>
        <child>l_thigh_pan</child>
        <axis>
          <dynamics>
            <damping>0</damping>
            <friction>0</friction>
            <spring_reference>0</spring_reference>
            <spring_stiffness>0</spring_stiffness>
          </dynamics>
          <limit>
            <lower>-1.5708</lower>
            <upper>1.5708</upper>
            <effort>0</effort>
            <velocity>0</velocity>
          </limit>
          <xyz>0 0 1</xyz>
          <use_parent_model_frame>1</use_parent_model_frame>
        </axis>
      </joint>
      <joint name='l_thigh_lift_joint' type='revolute'>
        <parent>l_thigh_pan</parent>
        <child>l_thigh_lift</child>
        <axis>
          <dynamics>
            <damping>0</damping>
            <friction>0</friction>
            <spring_reference>0</spring_reference>
            <spring_stiffness>0</spring_stiffness>
          </dynamics>
          <limit>
            <lower>-1.5708</lower>
            <upper>1.5708</upper>
            <effort>0</effort>
            <velocity>0</velocity>
          </limit>
          <xyz>0 1 0</xyz>
          <use_parent_model_frame>1</use_parent_model_frame>
        </axis>
      </joint>
      <joint name='l_calf_joint' type='revolute'>
        <parent>l_thigh_lift</parent>
        <child>l_calf</child>
        <axis>
          <dynamics>
            <damping>0</damping>
            <friction>0</friction>
            <spring_reference>0</spring_reference>
            <spring_stiffness>0</spring_stiffness>
          </dynamics>
          <limit>
            <lower>-1.5708</lower>
            <upper>1.5708</upper>
            <effort>0</effort>
            <velocity>0</velocity>
          </limit>
          <xyz>0 1 0</xyz>
          <use_parent_model_frame>1</use_parent_model_frame>
        </axis>
      </joint>
      <joint name='l_ankle_joint' type='revolute'>
        <parent>l_calf</parent>
        <child>l_ankle</child>
        <axis>
          <dynamics>
            <damping>0</damping>
            <friction>0</friction>
            <spring_reference>0</spring_reference>
            <spring_stiffness>0</spring_stiffness>
          </dynamics>
          <limit>
            <lower>-1.5708</lower>
            <upper>1.5708</upper>
            <effort>0</effort>
            <velocity>0</velocity>
          </limit>
          <xyz>0 1 0</xyz>
          <use_parent_model_frame>1</use_parent_model_frame>
        </axis>
      </joint>
      <joint name='l_foot_joint' type='revolute'>
        <parent>l_ankle</parent>
        <child>l_foot</child>
        <axis>
          <dynamics>
            <damping>0</damping>
            <friction>0</friction>
            <spring_reference>0</spring_reference>
            <spring_stiffness>0</spring_stiffness>
          </dynamics>
          <limit>
            <lower>-1.5708</lower>
            <upper>1.5708</upper>
            <effort>0</effort>
            <velocity>0</velocity>
          </limit>
          <xyz>1 0 0</xyz>
          <use_parent_model_frame>1</use_parent_model_frame>
        </axis>
      </joint>
      <joint name='r_thigh_pan_joint' type='revolute'>
        <parent>hip</parent>
        <child>r_thigh_pan</child>
        <axis>
          <dynamics>
            <damping>0</damping>
            <friction>0</friction>
            <spring_reference>0</spring_reference>
            <spring_stiffness>0</spring_stiffness>
          </dynamics>
          <limit>
            <lower>-1.5708</lower>
            <upper>1.5708</upper>
            <effort>0</effort>
            <velocity>0</velocity>
          </limit>
          <xyz>0 0 1</xyz>
          <use_parent_model_frame>1</use_parent_model_frame>
        </axis>
      </joint>
      <joint name='r_thigh_lift_joint' type='revolute'>
        <parent>r_thigh_pan</parent>
        <child>r_thigh_lift</child>
        <axis>
          <dynamics>
            <damping>0</damping>
            <friction>0</friction>
            <spring_reference>0</spring_reference>
            <spring_stiffness>0</spring_stiffness>
          </dynamics>
          <limit>
            <lower>-1.5708</lower>
            <upper>1.5708</upper>
            <effort>0</effort>
            <velocity>0</velocity>
          </limit>
          <xyz>0 1 0</xyz>
          <use_parent_model_frame>1</use_parent_model_frame>
        </axis>
      </joint>
      <joint name='r_calf_joint' type='revolute'>
        <parent>r_thigh_lift</parent>
        <child>r_calf</child>
        <axis>
          <dynamics>
            <damping>0</damping>
            <friction>0</friction>
            <spring_reference>0</spring_reference>
            <spring_stiffness>0</spring_stiffness>
          </dynamics>
          <limit>
            <lower>-1.5708</lower>
            <upper>1.5708</upper>
            <effort>0</effort>
            <velocity>0</velocity>
          </limit>
          <xyz>0 1 0</xyz>
          <use_parent_model_frame>1</use_parent_model_frame>
        </axis>
      </joint>
      <joint name='r_ankle_joint' type='revolute'>
        <parent>r_calf</parent>
        <child>r_ankle</child>
        <axis>
          <dynamics>
            <damping>0</damping>
            <friction>0</friction>
            <spring_reference>0</spring_reference>
            <spring_stiffness>0</spring_stiffness>
          </dynamics>
          <limit>
            <lower>-1.5708</lower>
            <upper>1.5708</upper>
            <effort>0</effort>
            <velocity>0</velocity>
          </limit>
          <xyz>0 1 0</xyz>
          <use_parent_model_frame>1</use_parent_model_frame>
        </axis>
      </joint>
      <joint name='r_foot_joint' type='revolute'>
        <parent>r_ankle</parent>
        <child>r_foot</child>
        <axis>
          <dynamics>
            <damping>0</damping>
            <friction>0</friction>
            <spring_reference>0</spring_reference>
            <spring_stiffness>0</spring_stiffness>
          </dynamics>
          <limit>
            <lower>-1.5708</lower>
            <upper>1.5708</upper>
            <effort>0</effort>
            <velocity>0</velocity>
          </limit>
          <xyz>1 0 0</xyz>
          <use_parent_model_frame>1</use_parent_model_frame>
        </axis>
      </joint>
      <joint name='torso_joint' type='revolute'>
        <parent>hip</parent>
        <child>torso</child>
        <axis>
          <dynamics>
            <damping>0</damping>
            <friction>0</friction>
            <spring_reference>0</spring_reference>
            <spring_stiffness>0</spring_stiffness>
          </dynamics>
          <limit>
            <lower>-1.5708</lower>
            <upper>1.5708</upper>
            <effort>0</effort>
            <velocity>0</velocity>
          </limit>
          <xyz>0 1 0</xyz>
          <use_parent_model_frame>1</use_parent_model_frame>
        </axis>
      </joint>
      <joint name='l_shoulder_joint' type='revolute'>
        <parent>torso</parent>
        <child>l_shoulder</child>
        <axis>
          <dynamics>
            <damping>0</damping>
            <friction>0</friction>
            <spring_reference>0</spring_reference>
            <spring_stiffness>0</spring_stiffness>
          </dynamics>
          <limit>
            <lower>-1.5708</lower>
            <upper>1.5708</upper>
            <effort>0</effort>
            <velocity>0</velocity>
          </limit>
          <xyz>1 0 0</xyz>
          <use_parent_model_frame>1</use_parent_model_frame>
        </axis>
      </joint>
      <joint name='l_upper_arm_joint' type='revolute'>
        <parent>l_shoulder</parent>
        <child>l_upper_arm</child>
        <axis>
          <dynamics>
            <damping>0</damping>
            <friction>0</friction>
            <spring_reference>0</spring_reference>
            <spring_stiffness>0</spring_stiffness>
          </dynamics>
          <limit>
            <lower>-1.5708</lower>
            <upper>1.5708</upper>
            <effort>0</effort>
            <velocity>0</velocity>
          </limit>
          <xyz>0 1 0</xyz>
          <use_parent_model_frame>1</use_parent_model_frame>
        </axis>
      </joint>
      <joint name='l_forearm_joint' type='revolute'>
        <parent>l_upper_arm</parent>
        <child>l_forearm</child>
        <axis>
          <dynamics>
            <damping>0</damping>
            <friction>0</friction>
            <spring_reference>0</spring_reference>
            <spring_stiffness>0</spring_stiffness>
          </dynamics>
          <limit>
            <lower>-1.5708</lower>
            <upper>1.5708</upper>
            <effort>0</effort>
            <velocity>0</velocity>
          </limit>
          <xyz>0 1 0</xyz>
          <use_parent_model_frame>1</use_parent_model_frame>
        </axis>
      </joint>
      <joint name='l_wrist_joint' type='revolute'>
        <parent>l_forearm</parent>
        <child>l_wrist</child>
        <axis>
          <dynamics>
            <damping>0</damping>
            <friction>0</friction>
            <spring_reference>0</spring_reference>
            <spring_stiffness>0</spring_stiffness>
          </dynamics>
          <limit>
            <lower>-1.5708</lower>
            <upper>1.5708</upper>
            <effort>0</effort>
            <velocity>0</velocity>
          </limit>
          <xyz>0 1 0</xyz>
          <use_parent_model_frame>1</use_parent_model_frame>
        </axis>
      </joint>
      <joint name='l_hand_joint' type='revolute'>
        <parent>l_wrist</parent>
        <child>l_hand</child>
        <axis>
          <dynamics>
            <damping>0</damping>
            <friction>0</friction>
            <spring_reference>0</spring_reference>
            <spring_stiffness>0</spring_stiffness>
          </dynamics>
          <limit>
            <lower>-1.5708</lower>
            <upper>1.5708</upper>
            <effort>0</effort>
            <velocity>0</velocity>
          </limit>
          <xyz>0 1 0</xyz>
          <use_parent_model_frame>1</use_parent_model_frame>
        </axis>
      </joint>
      <joint name='neck_joint' type='revolute'>
        <parent>torso</parent>
        <child>neck</child>
        <axis>
          <dynamics>
            <damping>0</damping>
            <friction>0</friction>
            <spring_reference>0</spring_reference>
            <spring_stiffness>0</spring_stiffness>
          </dynamics>
          <limit>
            <lower>-1.5708</lower>
            <upper>1.5708</upper>
            <effort>0</effort>
            <velocity>0</velocity>
          </limit>
          <xyz>0 0 1</xyz>
          <use_parent_model_frame>1</use_parent_model_frame>
        </axis>
      </joint>
      <joint name='head_joint' type='revolute'>
        <parent>neck</parent>
        <child>head</child>
        <axis>
          <dynamics>
            <damping>0</damping>
            <friction>0</friction>
            <spring_reference>0</spring_reference>
            <spring_stiffness>0</spring_stiffness>
          </dynamics>
          <limit>
            <lower>-1.5708</lower>
            <upper>1.5708</upper>
            <effort>0</effort>
            <velocity>0</velocity>
          </limit>
          <xyz>0 1 0</xyz>
          <use_parent_model_frame>1</use_parent_model_frame>
        </axis>
      </joint>
      <joint name='r_shoulder_joint' type='revolute'>
        <parent>torso</parent>
        <child>r_shoulder</child>
        <axis>
          <dynamics>
            <damping>0</damping>
            <friction>0</friction>
            <spring_reference>0</spring_reference>
            <spring_stiffness>0</spring_stiffness>
          </dynamics>
          <limit>
            <lower>-1.5708</lower>
            <upper>1.5708</upper>
            <effort>0</effort>
            <velocity>0</velocity>
          </limit>
          <xyz>1 0 0</xyz>
          <use_parent_model_frame>1</use_parent_model_frame>
        </axis>
      </joint>
      <joint name='r_upper_arm_joint' type='revolute'>
        <parent>r_shoulder</parent>
        <child>r_upper_arm</child>
        <axis>
          <dynamics>
            <damping>0</damping>
            <friction>0</friction>
            <spring_reference>0</spring_reference>
            <spring_stiffness>0</spring_stiffness>
          </dynamics>
          <limit>
            <lower>-1.5708</lower>
            <upper>1.5708</upper>
            <effort>0</effort>
            <velocity>0</velocity>
          </limit>
          <xyz>0 1 0</xyz>
          <use_parent_model_frame>1</use_parent_model_frame>
        </axis>
      </joint>
      <joint name='r_forearm_joint' type='revolute'>
        <parent>r_upper_arm</parent>
        <child>r_forearm</child>
        <axis>
          <dynamics>
            <damping>0</damping>
            <friction>0</friction>
            <spring_reference>0</spring_reference>
            <spring_stiffness>0</spring_stiffness>
          </dynamics>
          <limit>
            <lower>-1.5708</lower>
            <upper>1.5708</upper>
            <effort>0</effort>
            <velocity>0</velocity>
          </limit>
          <xyz>0 1 0</xyz>
          <use_parent_model_frame>1</use_parent_model_frame>
        </axis>
      </joint>
      <joint name='r_wrist_joint' type='revolute'>
        <parent>r_forearm</parent>
        <child>r_wrist</child>
        <axis>
          <dynamics>
            <damping>0</damping>
            <friction>0</friction>
            <spring_reference>0</spring_reference>
            <spring_stiffness>0</spring_stiffness>
          </dynamics>
          <limit>
            <lower>-1.5708</lower>
            <upper>1.5708</upper>
            <effort>0</effort>
            <velocity>0</velocity>
          </limit>
          <xyz>0 1 0</xyz>
          <use_parent_model_frame>1</use_parent_model_frame>
        </axis>
      </joint>
      <joint name='r_hand_joint' type='revolute'>
        <parent>r_wrist</parent>
        <child>r_hand</child>
        <axis>
          <dynamics>
            <damping>0</damping>
            <friction>0</friction>
            <spring_reference>0</spring_reference>
            <spring_stiffness>0</spring_stiffness>
          </dynamics>
          <limit>
            <lower>-1.5708</lower>
            <upper>1.5708</upper>
            <effort>0</effort>
            <velocity>0</velocity>
          </limit>
          <xyz>0 1 0</xyz>
          <use_parent_model_frame>1</use_parent_model_frame>
        </axis>
      </joint>
      <static>0</static>
    </model>
    <model name='postbox'>
      <static>1</static>
      <link name='link'>
        <collision name='collision'>
          <geometry>
            <mesh>
              <uri>model://postbox/meshes/postbox.dae</uri>
            </mesh>
          </geometry>
          <max_contacts>10</max_contacts>
          <surface>
            <contact>
              <ode/>
            </contact>
            <bounce/>
            <friction>
              <torsional>
                <ode/>
              </torsional>
              <ode/>
            </friction>
          </surface>
        </collision>
        <visual name='visual'>
          <geometry>
            <mesh>
              <uri>model://postbox/meshes/postbox.dae</uri>
            </mesh>
          </geometry>
        </visual>
        <self_collide>0</self_collide>
        <enable_wind>0</enable_wind>
        <kinematic>0</kinematic>
      </link>
      <pose frame=''>4.16393 2.74526 0 0 -0 0</pose>
    </model>
    <model name='unit_cylinder'>
      <pose frame=''>-0.98327 -1.74713 0.5 0 -0 0</pose>
      <link name='link'>
        <inertial>
          <mass>1</mass>
          <inertia>
            <ixx>0.145833</ixx>
            <ixy>0</ixy>
            <ixz>0</ixz>
            <iyy>0.145833</iyy>
            <iyz>0</iyz>
            <izz>0.125</izz>
          </inertia>
        </inertial>
        <collision name='collision'>
          <geometry>
            <cylinder>
              <radius>0.5</radius>
              <length>1</length>
            </cylinder>
          </geometry>
          <max_contacts>10</max_contacts>
          <surface>
            <contact>
              <ode/>
            </contact>
            <bounce/>
            <friction>
              <torsional>
                <ode/>
              </torsional>
              <ode/>
            </friction>
          </surface>
        </collision>
        <visual name='visual'>
          <geometry>
            <cylinder>
              <radius>0.5</radius>
              <length>1</length>
            </cylinder>
          </geometry>
          <material>
            <script>
              <name>Gazebo/Grey</name>
              <uri>file://media/materials/scripts/gazebo.material</uri>
            </script>
          </material>
        </visual>
        <self_collide>0</self_collide>
        <enable_wind>0</enable_wind>
        <kinematic>0</kinematic>
      </link>
    </model>
    <model name='unit_cylinder_0'>
      <pose frame=''>-0.994163 1.87885 0.5 0 -0 0</pose>
      <link name='link'>
        <inertial>
          <mass>1</mass>
          <inertia>
            <ixx>0.145833</ixx>
            <ixy>0</ixy>
            <ixz>0</ixz>
            <iyy>0.145833</iyy>
            <iyz>0</iyz>
            <izz>0.125</izz>
          </inertia>
        </inertial>
        <collision name='collision'>
          <geometry>
            <cylinder>
              <radius>0.5</radius>
              <length>1</length>
            </cylinder>
          </geometry>
          <max_contacts>10</max_contacts>
          <surface>
            <contact>
              <ode/>
            </contact>
            <bounce/>
            <friction>
              <torsional>
                <ode/>
              </torsional>
              <ode/>
            </friction>
          </surface>
        </collision>
        <visual name='visual'>
          <geometry>
            <cylinder>
              <radius>0.5</radius>
              <length>1</length>
            </cylinder>
          </geometry>
          <material>
            <script>
              <name>Gazebo/Grey</name>
              <uri>file://media/materials/scripts/gazebo.material</uri>
            </script>
          </material>
        </visual>
        <self_collide>0</self_collide>
        <enable_wind>0</enable_wind>
        <kinematic>0</kinematic>
      </link>
    </model>
    <model name='unit_box'>
      <pose frame=''>1.0812 -1.7721 0.5 0 -0 0</pose>
      <link name='link'>
        <inertial>
          <mass>1</mass>
          <inertia>
            <ixx>0.166667</ixx>
            <ixy>0</ixy>
            <ixz>0</ixz>
            <iyy>0.166667</iyy>
            <iyz>0</iyz>
            <izz>0.166667</izz>
          </inertia>
        </inertial>
        <collision name='collision'>
          <geometry>
            <box>
              <size>1 1 1</size>
            </box>
          </geometry>
          <max_contacts>10</max_contacts>
          <surface>
            <contact>
              <ode/>
            </contact>
            <bounce/>
            <friction>
              <torsional>
                <ode/>
              </torsional>
              <ode/>
            </friction>
          </surface>
        </collision>
        <visual name='visual'>
          <geometry>
            <box>
              <size>1 1 1</size>
            </box>
          </geometry>
          <material>
            <script>
              <name>Gazebo/Grey</name>
              <uri>file://media/materials/scripts/gazebo.material</uri>
            </script>
          </material>
        </visual>
        <self_collide>0</self_collide>
        <enable_wind>0</enable_wind>
        <kinematic>0</kinematic>
      </link>
    </model>
  </world>
</sdf>
